Workbook

Sheet Traceability Matrix
A1: Epic | B1: Ticket | C1: AC ID | D1: AC təsviri (qısa, GRAD-AC-Reference.md-dən) | E1: Prioritet (TestPlan/AC-Reference) | F1: Avtomatlaşdırma statusu (Gauge) | G1: Gauge spec faylı | H1: Spec ssenari(ləri) | I1: Qeyd / Gap izahı | J1: RestAssured test(lər)i (grad-restassured-testng) | K1: RestAssured statusu (son tam icra 09.10.2026: 147/147 passed) | L1: Test case ID(lər) — docs/Test-Cases-UI-API.xlsx | M1: Son nəticə (09.10.2026) | N1: Bug
A2: EPIC-1: Saxlanmış alıcılar | B2: GRAD-101 | C2: AC-1 | D2: Etibarlı sorğu → 201; id/iban/ibanMasked/currency/nickname/createdAt + Location header | E2: High (5 SP) | F2: Tam | G2: gradBeneficiaryTesting.spec | H2: #1 | I2: Bütün sahələr və Location header yoxlanılır. | J2: BeneficiaryCreateTest.ac1_validRequest_returns201WithAllFields | K2: Avtomat — 2026-10-07 passed | L2: TC-API-BEN-101-01 | M2: Passed
A3: EPIC-1: Saxlanmış alıcılar | B3: GRAD-101 | C3: AC-2 | D3: IBAN normallaşdırma (boşluq+kiçik hərf → təmiz+böyük hərf) | E3: High (5 SP) | F3: Tam | G3: gradBeneficiaryTesting.spec | H3: #2 | J3: BeneficiaryCreateTest.ac2_ibanNormalization_spacesAndLowercase | K3: Avtomat — 2026-10-07 passed | L3: TC-API-BEN-101-02 | M3: Passed
A4: EPIC-1: Saxlanmış alıcılar | B4: GRAD-101 | C4: AC-3 | D4: nickname göndərilmədikdə null qaytarılır | E4: High (5 SP) | F4: Tam | G4: gradBeneficiaryTesting.spec | H4: #3 | J4: BeneficiaryCreateTest.ac3_nicknameNotSent_returnsNull | K4: Avtomat — 2026-10-07 passed | L4: TC-API-BEN-101-03 | M4: Passed
A5: EPIC-1: Saxlanmış alıcılar | B5: GRAD-101 | C5: AC-4 | D5: Bir neçə sahə eyni anda səhv → 400 VALIDATION_ERROR, details[] | E5: High (5 SP) | F5: Tam | G5: gradBeneficiaryTesting.spec | H5: #4 | I5: details ölçüsü 2 təsdiqlənir. | J5: BeneficiaryCreateTest.ac4_multipleInvalidFields_returns400WithTwoDetails | K5: Avtomat — 2026-10-07 passed | L5: TC-API-BEN-101-04 | M5: Passed
A6: EPIC-1: Saxlanmış alıcılar | B6: GRAD-101 | C6: AC-5 | D6: fullName uzunluq sərhədi: 1/51 rədd, 2/50 qəbul | E6: High (5 SP) | F6: Tam | G6: gradBeneficiaryTesting.spec | H6: #5,#6,#7,#8 | I6: 4 sərhəd dəyəri də ayrıca test olunur. | J6: BeneficiaryCreateTest.ac5_fullNameLengthBoundary | K6: Avtomat — 2026-10-07 passed | L6: TC-API-BEN-101-05 TC-API-BEN-101-06 TC-API-BEN-101-07 TC-API-BEN-101-08 | M6: Passed
A7: EPIC-1: Saxlanmış alıcılar | B7: GRAD-101 | C7: AC-6 | D7: fullName format: hərflə başlamır / rəqəm var → 400 | E7: High (5 SP) | F7: Tam | G7: gradBeneficiaryTesting.spec | H7: #9,#10 | J7: BeneficiaryCreateTest.ac6_fullNameInvalidFormat_returns400 | K7: Avtomat — 2026-10-07 passed | L7: TC-API-BEN-101-09 TC-API-BEN-101-10 TC-API-BEN-101-20 | M7: Passed
A8: EPIC-1: Saxlanmış alıcılar | B8: GRAD-101 | C8: AC-7 | D8: Eyni IBAN təkrar → 409 BENEFICIARY_EXISTS | E8: High (5 SP) | F8: Tam | G8: gradBeneficiaryTesting.spec | H8: #11 | J8: BeneficiaryCreateTest.ac7_duplicateIban_returns409 | K8: Avtomat — 2026-10-07 passed | L8: TC-API-BEN-101-11 | M8: Passed
A9: EPIC-1: Saxlanmış alıcılar | B9: GRAD-101 | C9: AC-8 | D9: nickname unikallığı (case-insensitive) → 409 NICKNAME_TAKEN | E9: High (5 SP) | F9: Tam | G9: gradBeneficiaryTesting.spec | H9: #12 | J9: BeneficiaryCreateTest.ac8_nicknameUniqueness_caseInsensitive_returns409 | K9: Avtomat — 2026-10-07 passed | L9: TC-API-BEN-101-12 | M9: Passed
A10: EPIC-1: Saxlanmış alıcılar | B10: GRAD-101 | C10: AC-9 | D10: Öz hesabının IBAN-ı → 422 OWN_ACCOUNT | E10: High (5 SP) | F10: Tam | G10: gradBeneficiaryTesting.spec | H10: #13 | J10: BeneficiaryCreateTest.ac9_ownAccountIban_returns422 | K10: Avtomat — 2026-10-07 passed | L10: TC-API-BEN-101-13 | M10: Passed
A11: EPIC-1: Saxlanmış alıcılar | B11: GRAD-101 | C11: AC-10 | D11: 11-ci alıcı → 422 LIMIT_REACHED, limit:10 | E11: High (5 SP) | F11: Tam | G11: gradBeneficiaryTesting.spec | H11: #14 | J11: BeneficiaryCreateTest.ac10_eleventhBeneficiary_returns422LimitReached | K11: Avtomat — 2026-10-07 passed | L11: TC-API-BEN-101-14 | M11: Passed
A12: EPIC-1: Saxlanmış alıcılar | B12: GRAD-101 | C12: Əlavə | D12: Token yox/saxta → 401; JSON deyil → 400 INVALID_JSON; SQLi/XSS; IBAN 27/29 simvol sərhədi; AZ hərf/defis/apostrof qəbulu | E12: High (5 SP) | F12: Tam (AC-dən əlavə) | G12: gradBeneficiaryTesting.spec | H12: #15-#22 | I12: Bu ssenarilər konkret nömrələnmiş AC-yə bağlı deyil, lakin Ümumi texniki qaydaları və əlavə BVA/security örtür. | J12: BeneficiaryCreateTest.extra_noToken_returns401 BeneficiaryCreateTest.extra_fakeToken_returns401 BeneficiaryCreateTest.extra_sqlInjectionInFullName_returns400 BeneficiaryCreateTest.extra_xssInNickname_returns400 BeneficiaryCreateTest.extra_invalidJsonBody_returns400InvalidJson BeneficiaryCreateTest.extra_azerbaijaniLettersHyphenApostrophe_accepted BeneficiaryCreateTest.extra_ibanLengthBoundary_returns400 | K12: Avtomat — 2026-10-07 passed | L12: TC-API-BEN-101-15 TC-API-BEN-101-16 TC-API-BEN-101-17 TC-API-BEN-101-18 TC-API-BEN-101-19 TC-API-BEN-101-21 TC-API-BEN-101-22 | M12: Passed
A13: EPIC-1: Saxlanmış alıcılar | B13: GRAD-102 | C13: AC-1 | D13: Parametrsiz → 200; total=items.length; ən yeni birinci | E13: Medium (3 SP) | F13: Tam | G13: gradListBeneficiaries.spec | H13: 'Parametrsiz siyahı - defolt sıralama yeni-ucdan' | J13: BeneficiaryListTest.ac1_noParams_defaultSortNewestFirst | K13: Avtomat — 2026-10-07 passed | L13: TC-API-BEN-102-06 | M13: Passed
A14: EPIC-1: Saxlanmış alıcılar | B14: GRAD-102 | C14: AC-2 | D14: sort=fullName&order=asc → əlifba sırası (AZ əlifbası) | E14: Medium (3 SP) | F14: Tam | G14: gradListBeneficiaries.spec | H14: 'Adla sıralama - əlifba sırası ilə (asc)' | J14: BeneficiaryListTest.ac2_sortByFullNameAsc | K14: Avtomat — 2026-10-07 passed | L14: TC-API-BEN-102-07 | M14: Passed
A15: EPIC-1: Saxlanmış alıcılar | B15: GRAD-102 | C15: AC-3 | D15: currency=USD → yalnız USD alıcılar | E15: Medium (3 SP) | F15: Qismən | G15: gradListBeneficiaries.spec | H15: 'Valyuta filtri - yalnız USD alıcılar' | I15: GAP: Bu ssenari 2 alıcı yaradır, lakin currency=USD ilə GET sorğusunu heç vaxt göndərmir və heç bir assertion etmir (spec faylı, sətir 69-101) — AC-3 həqiqətən test edilmir. Kombinə edilmiş filtr testi (Əlavə sətri) currency parametrini istifadə edir, amma təkbaşına AC-3-ü əhatə etmir. | J15: BeneficiaryListTest.ac3_currencyFilter_usdOnly | K15: Avtomat — 2026-10-07 passed | L15: TC-API-BEN-102-05 | M15: Passed
A16: EPIC-1: Saxlanmış alıcılar | B16: GRAD-102 | C16: AC-4 | D16: q=NİGAR / q=NIGAR (nöqtəsiz I) → hər iki halda tapılır | E16: Medium (3 SP) | F16: Tam | G16: gradListBeneficiaries.spec | H16: 'Case-folding axtarış - İ/I herf problemi' | J16: BeneficiaryListTest.ac4_caseFoldingSearch_turkishIProblem | K16: Avtomat — 2026-10-07 passed | L16: TC-API-BEN-102-08 | M16: Passed
A17: EPIC-1: Saxlanmış alıcılar | B17: GRAD-102 | C17: AC-5 | D17: q ləqəbin bir hissəsidir → ləqəbə görə də tapılır | E17: Medium (3 SP) | F17: Tam | G17: gradListBeneficiaries.spec | H17: 'Ləqəbin bir hissəsi ile axtarış' | J17: BeneficiaryListTest.ac5_nicknamePartialSearch | K17: Avtomat — 2026-10-07 passed | L17: TC-API-BEN-102-11 | M17: Passed
A18: EPIC-1: Saxlanmış alıcılar | B18: GRAD-102 | C18: AC-6 | D18: q=a (1 simvol) → 400 VALIDATION_ERROR, field:q | E18: Medium (3 SP) | F18: Tam | G18: gradListBeneficiaries.spec | H18: 'q parametri minimum uzunluqdan qısadır' | J18: BeneficiaryListTest.ac6_qTooShort_returns400ValidationError | K18: Avtomat — 2026-10-07 passed | L18: TC-API-BEN-102-03 | M18: Passed
A19: EPIC-1: Saxlanmış alıcılar | B19: GRAD-102 | C19: AC-7 | D19: Heç nə tapılmır → 200, total:0, items:[] | E19: Medium (3 SP) | F19: Tam | G19: gradListBeneficiaries.spec | H19: 'Mövcud olmayan adla axtarış - heç ne tapılmır' | J19: BeneficiaryListTest.ac7_noResults_returns200EmptyList | K19: Avtomat — 2026-10-07 passed | L19: TC-API-BEN-102-02 | M19: Passed
A20: EPIC-1: Saxlanmış alıcılar | B20: GRAD-102 | C20: Əlavə | D20: Token yoxdur → 401; etibarsız sort dəyəri → 400; SQLi (q) → 200-400 aralığı; kombinə edilmiş filtrlər (q+currency+sort+order) | E20: Medium (3 SP) | F20: Tam (AC-dən əlavə) | G20: gradListBeneficiaries.spec | H20: 'Token olmadan GET', 'Etibarsız sort dəyeri', 'SQL-injection...', 'Kombinə edilmiş filtrlər...' | I20: Kombinə edilmiş filtr testi AC-2/3/4-ü birlikdə əlavə təsdiqləyir. | J20: BeneficiaryListTest.extra_noToken_returns401 BeneficiaryListTest.extra_sqlInjectionInQ_returns200to400 BeneficiaryListTest.extra_invalidSortValue_returns400 BeneficiaryListTest.extra_combinedFilters_qCurrencySortOrder | K20: Avtomat — 2026-10-07 passed | L20: TC-API-BEN-102-01 TC-API-BEN-102-04 TC-API-BEN-102-09 TC-API-BEN-102-10 | M20: Passed
A21: EPIC-1: Saxlanmış alıcılar | B21: GRAD-103 | C21: AC-1 | D21: Mövcud alıcı silinir → 204, body boşdur | E21: Medium (2 SP) | F21: Tam | G21: gradDeleteBeneficiary.spec | H21: 'Movcud alicini silmek' | J21: BeneficiaryDeleteTest.ac1_deleteExistingBeneficiary_returns204EmptyBody | K21: Avtomat — 2026-10-07 passed | L21: TC-API-BEN-103-01 | M21: Passed
A22: EPIC-1: Saxlanmış alıcılar | B22: GRAD-103 | C22: AC-2 | D22: Silinmiş alıcı siyahıda yoxdur, total 1 azalıb | E22: Medium (2 SP) | F22: Tam | G22: gradDeleteBeneficiary.spec | H22: 'Silinmiş alıcı siyahıda görünmür' | J22: BeneficiaryDeleteTest.ac2_deletedBeneficiaryNotInList_totalDecreasesByOne | K22: Avtomat — 2026-10-07 passed | L22: TC-API-BEN-103-02 | M22: Passed
A23: EPIC-1: Saxlanmış alıcılar | B23: GRAD-103 | C23: AC-3 | D23: Eyni id ikinci dəfə silinir → 404 NOT_FOUND | E23: Medium (2 SP) | F23: Tam | G23: gradDeleteBeneficiary.spec | H23: 'Eyni id ikinci defe silinir' | J23: BeneficiaryDeleteTest.ac3_sameIdDeletedTwice_secondReturns404 | K23: Avtomat — 2026-10-07 passed | L23: TC-API-BEN-103-03 | M23: Passed
A24: EPIC-1: Saxlanmış alıcılar | B24: GRAD-103 | C24: AC-4 | D24: user2 user1-in alıcı id-si ilə silməyə çalışır → 404 (403 yox) (IDOR) | E24: Medium (2 SP) | F24: Tam | G24: gradDeleteBeneficiary.spec | H24: 'Başqa istifadəçinin alıcısını silmək (IDOR)' | J24: BeneficiaryDeleteTest.ac4_idorAnotherUsersBeneficiary_returns404NotFound | K24: Avtomat — 2026-10-07 passed | L24: TC-API-BEN-103-06 | M24: Passed
A25: EPIC-1: Saxlanmış alıcılar | B25: GRAD-103 | C25: Əlavə | D25: Token olmadan DELETE → 401; mövcud olmayan id → 404 | E25: Medium (2 SP) | F25: Tam (AC-dən əlavə) | G25: gradDeleteBeneficiary.spec | H25: 'Token olmadan DELETE sorğusu', 'Movcud olmayan id ile DELETE' | J25: BeneficiaryDeleteTest.extra_noToken_returns401 BeneficiaryDeleteTest.extra_nonExistentId_returns404 | K25: Avtomat — 2026-10-07 passed | L25: TC-API-BEN-103-04 TC-API-BEN-103-05 | M25: Passed
A26: EPIC-2: Virtual kartlar | B26: GRAD-201 | C26: AC-1 | D26: Etibarlı sorğu → 201; status ACTIVE; availableBalance=initialAmount; limitlər 500/300; spentToday 0 | E26: High (5 SP) | F26: Tam | G26: gradCreateCard.spec | H26: 'Etibarlı kart buraxılışı' | J26: CardCreateTest.validCardCreation_returns201WithAllFields CardCreateTest.labelNotSent_returnsNullLabel | K26: Avtomat — 2026-10-07 passed | L26: TC-API-CARD-201-01 TC-API-CARD-201-11 | M26: Passed
A27: EPIC-2: Virtual kartlar | B27: GRAD-201 | C27: AC-2 | D27: maskedPan '4169 73** **** NNNN' formatı; expiry MM/YY — bu gündən 3 il sonra | E27: High (5 SP) | F27: Qismən | G27: gradCreateCard.spec | H27: 'maskedPan/expiry formatı' | I27: Yalnız regex formatı (MM/YY) yoxlanılır; expiry-nin DƏQIQ 'bu gündən 3 il sonra' olduğu heç bir assertion-da hesablanıb müqayisə edilmir. | J27: CardCreateTest.maskedPanAndExpiry_matchExpectedFormat | K27: Avtomat — 2026-10-07 passed | L27: TC-API-CARD-201-02 | M27: Passed
A28: EPIC-2: Virtual kartlar | B28: GRAD-201 | C28: AC-3 | D28: initialAmount 0.99/1000.01 rədd; 1.00/1000.00 qəbul | E28: High (5 SP) | F28: Tam | G28: gradCreateCard.spec | H28: 'initialAmount sərhədi (BVA)' | J28: CardCreateTest.initialAmountBoundary_rejectsOrAccepts | K28: Avtomat — 2026-10-07 passed | L28: TC-API-CARD-201-03 | M28: Passed
A29: EPIC-2: Virtual kartlar | B29: GRAD-201 | C29: AC-4 | D29: initialAmount mətn ("50") və ya 10.555 → 400 | E29: High (5 SP) | F29: Tam | G29: gradCreateCard.spec | H29: 'initialAmount format xətaları' | J29: CardCreateTest.initialAmountFormatErrors_return400 | K29: Avtomat — 2026-10-07 passed | L29: TC-API-CARD-201-04 | M29: Passed
A30: EPIC-2: Virtual kartlar | B30: GRAD-201 | C30: AC-5 | D30: user1 acc_003 (özünə aid olmayan hesab) ilə kart açır → 403 FORBIDDEN | E30: High (5 SP) | F30: Tam | G30: gradCreateCard.spec | H30: 'Başqasının hesabı ilə kart açmaq' | J30: CardCreateTest.anotherUsersAccount_returns403 | K30: Avtomat — 2026-10-07 passed | L30: TC-API-CARD-201-05 | M30: Passed
A31: EPIC-2: Virtual kartlar | B31: GRAD-201 | C31: AC-6 | D31: user2 891 yükləmək istəyir (balans 890.50) → 422 INSUFFICIENT_FUNDS | E31: High (5 SP) | F31: YOXDUR | G31: gradCreateCard.spec | H31: — | I31: gradCreateCard.spec-də bu ssenari YOXDUR. Heç bir fayl bu AC-ni avtomatlaşdırmır. GAP. | J31: CardCreateTest.ac6_initialAmountExceedsAvailableBalance_returns422InsufficientFunds | K31: Avtomat — 2026-10-07 passed | L31: TC-API-CARD-201-12 | M31: Passed
A32: EPIC-2: Virtual kartlar | B32: GRAD-201 | C32: AC-7 | D32: 3 ACTIVE/FROZEN kart var, 4-cü açılır → 422 CARD_LIMIT_REACHED | E32: High (5 SP) | F32: Tam | G32: gradCreateCard.spec | H32: 'Kart limiti (3) aşılır' | J32: CardCreateTest.cardLimitExceeded_fourthCardReturns422 | K32: Avtomat — 2026-10-07 passed | L32: TC-API-CARD-201-06 | M32: Passed
A33: EPIC-2: Virtual kartlar | B33: GRAD-201 | C33: AC-8 | D33: Kartlardan biri BLOCKED edilib, yeni kart açılır → 201 (BLOCKED limitə sayılmır) | E33: High (5 SP) | F33: YOXDUR | G33: gradCreateCard.spec | H33: — | I33: Heç bir spec faylında test olunmur. GAP. | J33: CardCreateTest.ac8_blockedCardDoesNotCountTowardActiveCardLimit | K33: Avtomat — 2026-10-07 passed | L33: TC-API-CARD-201-13 | M33: Passed
A34: EPIC-2: Virtual kartlar | B34: GRAD-201 | C34: Əlavə | D34: Mövcud olmayan accountId → 404; token yox/saxta → 401; XSS label (qəbul, sanitize olunmur); label yoxdursa null | E34: High (5 SP) | F34: Tam (AC-dən əlavə) | G34: gradCreateCard.spec | H34: 'Mövcud olmayan accountId', 'Token yoxdur', 'Saxta token', 'XSS payload - label', 'label göndərilmədikdə null' | I34: XSS testi label-in sanitize olunmadığını (security tapıntısı deyil, davranış qeydi) göstərir. | J34: CardCreateTest.nonExistentAccountId_returns404 CardCreateTest.noToken_returns401 CardCreateTest.fakeToken_returns401 CardCreateTest.xssPayloadInLabel_returns201WithLabelEchoedVerbatim | K34: Avtomat — 2026-10-07 passed | L34: TC-API-CARD-201-07 TC-API-CARD-201-08 TC-API-CARD-201-09 TC-API-CARD-201-10 | M34: Passed
A35: EPIC-2: Virtual kartlar | B35: GRAD-202 | C35: AC-1 | D35: Yeni buraxılmış kart → GET nəticəsi POST cavabı ilə eynidir | E35: Medium (2 SP) | F35: Tam | G35: gradGetCard.spec | H35: '#46 Yeni buraxılmış kartın məlumatı' | J35: CardGetTest.newlyIssuedCard_returnsMatchingDetails | K35: Avtomat — 2026-10-07 passed | L35: TC-API-CARD-202-01 | M35: Passed
A36: EPIC-2: Virtual kartlar | B36: GRAD-202 | C36: AC-2 | D36: 50.50 AZN ödənişdən sonra availableBalance azalıb, spentToday artıb | E36: Medium (2 SP) | F36: Qismən | G36: gradGetCard.spec | H36: '#47 Ödənişdən sonra balansın düzgün əks olunması' | I36: Yalnız availableBalance (49.5) yoxlanılır; spentToday sahəsi HEÇ BİR testdə assert edilmir (bax GRAD-302 qeydi də). GAP. | J36: CardGetTest.afterPayment_balanceReflectsCorrectly BillPaymentTest.scenario70_validCityNetPayment_returns201WithAllFields | K36: Avtomat — 2026-10-07 passed | L36: TC-API-CARD-202-04 TC-API-CARD-202-06 | M36: Passed
A37: EPIC-2: Virtual kartlar | B37: GRAD-202 | C37: AC-3 | D37: Başqa istifadəçinin kart id-si → 404 NOT_FOUND (IDOR) | E37: Medium (2 SP) | F37: Tam | G37: gradGetCard.spec | H37: '#48 Başqa istifadəçinin kartına GET cəhdi (IDOR)' | J37: CardGetTest.anotherUsersCard_idor_returns404NotFound | K37: Avtomat — 2026-10-07 passed | L37: TC-API-CARD-202-05 | M37: Passed
A38: EPIC-2: Virtual kartlar | B38: GRAD-202 | C38: Əlavə | D38: Token yox → 401; mövcud olmayan kart id → 404 | E38: Medium (2 SP) | F38: Tam (AC-dən əlavə) | G38: gradGetCard.spec | H38: '#49, #50' | J38: CardGetTest.noToken_returns401 CardGetTest.nonExistentCardId_returns404 | K38: Avtomat — 2026-10-07 passed | L38: TC-API-CARD-202-02 TC-API-CARD-202-03 | M38: Passed
A39: EPIC-2: Virtual kartlar | B39: GRAD-203 | C39: AC-1 | D39: ACTIVE+TEMPORARY → 200 FROZEN, blockReason, blockedAt | E39: Qeyd olunmayıb (TestPlan-da GRAD-203/204/302 'ən yüksək prioritet' qrupuna aid edilib) | F39: Tam | G39: gradBlockCard.spec | H39: '#51' | J39: CardBlockTest.ac1_activeCardTemporaryReason_returns200Frozen | K39: Avtomat — 2026-10-07 passed | L39: TC-API-CARD-203-01 | M39: Passed
A40: EPIC-2: Virtual kartlar | B40: GRAD-203 | C40: AC-2 | D40: ACTIVE+LOST → 200 BLOCKED | E40: Qeyd olunmayıb (TestPlan-da GRAD-203/204/302 'ən yüksək prioritet' qrupuna aid edilib) | F40: Tam | G40: gradBlockCard.spec | H40: '#52' | J40: CardBlockTest.ac2_activeCardLostReason_returns200Blocked | K40: Avtomat — 2026-10-07 passed | L40: TC-API-CARD-203-02 | M40: Passed
...

Sheet Xülasə
A1: Ticket | B1: Cəmi AC | C1: Tam | D1: Qismən | E1: Yoxdur | F1: Avtomat spec faylı | G1: RestAssured: AC örtülüb | H1: RestAssured: AC örtülməyib | I1: Test case ilə örtülən AC (Test-Cases-UI-API.xlsx) | J1: Son nəticəsi Passed olan AC
A2: GRAD-101 | B2: =COUNTIFS('Traceability Matrix'!$B$2:$B$87,"GRAD-101",'Traceability Matrix'!$C$2:$C$87,"AC-*") | C2: =COUNTIFS('Traceability Matrix'!$B$2:$B$87,"GRAD-101",'Traceability Matrix'!$C$2:$C$87,"AC-*",'Traceability Matrix'!$F$2:$F$87,"Tam")+COUNTIFS('Traceability Matrix'!$B$2:$B$87,"GRAD-101",'Traceability Matrix'!$C$2:$C$87,"AC-*",'Traceability Matrix'!$F$2:$F$87,"Tam (çarpaz fayl)") | D2: =COUNTIFS('Traceability Matrix'!$B$2:$B$87,"GRAD-101",'Traceability Matrix'!$C$2:$C$87,"AC-*",'Traceability Matrix'!$F$2:$F$87,"Qismən")+COUNTIFS('Traceability Matrix'!$B$2:$B$87,"GRAD-101",'Traceability Matrix'!$C$2:$C$87,"AC-*",'Traceability Matrix'!$F$2:$F$87,"Qismən (deviation)") | E2: =COUNTIFS('Traceability Matrix'!$B$2:$B$87,"GRAD-101",'Traceability Matrix'!$C$2:$C$87,"AC-*",'Traceability Matrix'!$F$2:$F$87,"YOXDUR") | F2: gradBeneficiaryTesting.spec | G2: =COUNTIFS('Traceability Matrix'!$B$2:$B$87,"GRAD-101",'Traceability Matrix'!$C$2:$C$87,"AC-*",'Traceability Matrix'!$K$2:$K$87,"Avtomat*") | H2: =COUNTIFS('Traceability Matrix'!$B$2:$B$87,"GRAD-101",'Traceability Matrix'!$C$2:$C$87,"AC-*",'Traceability Matrix'!$K$2:$K$87,"YOXDUR") | I2: =COUNTIFS('Traceability Matrix'!$B$2:$B$87,"GRAD-101",'Traceability Matrix'!$C$2:$C$87,"AC-*",'Traceability Matrix'!$L$2:$L$87,"<>") | J2: =COUNTIFS('Traceability Matrix'!$B$2:$B$87,"GRAD-101",'Traceability Matrix'!$C$2:$C$87,"AC-*",'Traceability Matrix'!$M$2:$M$87,"Passed")
A3: GRAD-102 | B3: =COUNTIFS('Traceability Matrix'!$B$2:$B$87,"GRAD-102",'Traceability Matrix'!$C$2:$C$87,"AC-*") | C3: =COUNTIFS('Traceability Matrix'!$B$2:$B$87,"GRAD-102",'Traceability Matrix'!$C$2:$C$87,"AC-*",'Traceability Matrix'!$F$2:$F$87,"Tam")+COUNTIFS('Traceability Matrix'!$B$2:$B$87,"GRAD-102",'Traceability Matrix'!$C$2:$C$87,"AC-*",'Traceability Matrix'!$F$2:$F$87,"Tam (çarpaz fayl)") | D3: =COUNTIFS('Traceability Matrix'!$B$2:$B$87,"GRAD-102",'Traceability Matrix'!$C$2:$C$87,"AC-*",'Traceability Matrix'!$F$2:$F$87,"Qismən")+COUNTIFS('Traceability Matrix'!$B$2:$B$87,"GRAD-102",'Traceability Matrix'!$C$2:$C$87,"AC-*",'Traceability Matrix'!$F$2:$F$87,"Qismən (deviation)") | E3: =COUNTIFS('Traceability Matrix'!$B$2:$B$87,"GRAD-102",'Traceability Matrix'!$C$2:$C$87,"AC-*",'Traceability Matrix'!$F$2:$F$87,"YOXDUR") | F3: gradListBeneficiaries.spec | G3: =COUNTIFS('Traceability Matrix'!$B$2:$B$87,"GRAD-102",'Traceability Matrix'!$C$2:$C$87,"AC-*",'Traceability Matrix'!$K$2:$K$87,"Avtomat*") | H3: =COUNTIFS('Traceability Matrix'!$B$2:$B$87,"GRAD-102",'Traceability Matrix'!$C$2:$C$87,"AC-*",'Traceability Matrix'!$K$2:$K$87,"YOXDUR") | I3: =COUNTIFS('Traceability Matrix'!$B$2:$B$87,"GRAD-102",'Traceability Matrix'!$C$2:$C$87,"AC-*",'Traceability Matrix'!$L$2:$L$87,"<>") | J3: =COUNTIFS('Traceability Matrix'!$B$2:$B$87,"GRAD-102",'Traceability Matrix'!$C$2:$C$87,"AC-*",'Traceability Matrix'!$M$2:$M$87,"Passed")
A4: GRAD-103 | B4: =COUNTIFS('Traceability Matrix'!$B$2:$B$87,"GRAD-103",'Traceability Matrix'!$C$2:$C$87,"AC-*") | C4: =COUNTIFS('Traceability Matrix'!$B$2:$B$87,"GRAD-103",'Traceability Matrix'!$C$2:$C$87,"AC-*",'Traceability Matrix'!$F$2:$F$87,"Tam")+COUNTIFS('Traceability Matrix'!$B$2:$B$87,"GRAD-103",'Traceability Matrix'!$C$2:$C$87,"AC-*",'Traceability Matrix'!$F$2:$F$87,"Tam (çarpaz fayl)") | D4: =COUNTIFS('Traceability Matrix'!$B$2:$B$87,"GRAD-103",'Traceability Matrix'!$C$2:$C$87,"AC-*",'Traceability Matrix'!$F$2:$F$87,"Qismən")+COUNTIFS('Traceability Matrix'!$B$2:$B$87,"GRAD-103",'Traceability Matrix'!$C$2:$C$87,"AC-*",'Traceability Matrix'!$F$2:$F$87,"Qismən (deviation)") | E4: =COUNTIFS('Traceability Matrix'!$B$2:$B$87,"GRAD-103",'Traceability Matrix'!$C$2:$C$87,"AC-*",'Traceability Matrix'!$F$2:$F$87,"YOXDUR") | F4: gradDeleteBeneficiary.spec | G4: =COUNTIFS('Traceability Matrix'!$B$2:$B$87,"GRAD-103",'Traceability Matrix'!$C$2:$C$87,"AC-*",'Traceability Matrix'!$K$2:$K$87,"Avtomat*") | H4: =COUNTIFS('Traceability Matrix'!$B$2:$B$87,"GRAD-103",'Traceability Matrix'!$C$2:$C$87,"AC-*",'Traceability Matrix'!$K$2:$K$87,"YOXDUR") | I4: =COUNTIFS('Traceability Matrix'!$B$2:$B$87,"GRAD-103",'Traceability Matrix'!$C$2:$C$87,"AC-*",'Traceability Matrix'!$L$2:$L$87,"<>") | J4: =COUNTIFS('Traceability Matrix'!$B$2:$B$87,"GRAD-103",'Traceability Matrix'!$C$2:$C$87,"AC-*",'Traceability Matrix'!$M$2:$M$87,"Passed")
A5: GRAD-201 | B5: =COUNTIFS('Traceability Matrix'!$B$2:$B$87,"GRAD-201",'Traceability Matrix'!$C$2:$C$87,"AC-*") | C5: =COUNTIFS('Traceability Matrix'!$B$2:$B$87,"GRAD-201",'Traceability Matrix'!$C$2:$C$87,"AC-*",'Traceability Matrix'!$F$2:$F$87,"Tam")+COUNTIFS('Traceability Matrix'!$B$2:$B$87,"GRAD-201",'Traceability Matrix'!$C$2:$C$87,"AC-*",'Traceability Matrix'!$F$2:$F$87,"Tam (çarpaz fayl)") | D5: =COUNTIFS('Traceability Matrix'!$B$2:$B$87,"GRAD-201",'Traceability Matrix'!$C$2:$C$87,"AC-*",'Traceability Matrix'!$F$2:$F$87,"Qismən")+COUNTIFS('Traceability Matrix'!$B$2:$B$87,"GRAD-201",'Traceability Matrix'!$C$2:$C$87,"AC-*",'Traceability Matrix'!$F$2:$F$87,"Qismən (deviation)") | E5: =COUNTIFS('Traceability Matrix'!$B$2:$B$87,"GRAD-201",'Traceability Matrix'!$C$2:$C$87,"AC-*",'Traceability Matrix'!$F$2:$F$87,"YOXDUR") | F5: gradCreateCard.spec | G5: =COUNTIFS('Traceability Matrix'!$B$2:$B$87,"GRAD-201",'Traceability Matrix'!$C$2:$C$87,"AC-*",'Traceability Matrix'!$K$2:$K$87,"Avtomat*") | H5: =COUNTIFS('Traceability Matrix'!$B$2:$B$87,"GRAD-201",'Traceability Matrix'!$C$2:$C$87,"AC-*",'Traceability Matrix'!$K$2:$K$87,"YOXDUR") | I5: =COUNTIFS('Traceability Matrix'!$B$2:$B$87,"GRAD-201",'Traceability Matrix'!$C$2:$C$87,"AC-*",'Traceability Matrix'!$L$2:$L$87,"<>") | J5: =COUNTIFS('Traceability Matrix'!$B$2:$B$87,"GRAD-201",'Traceability Matrix'!$C$2:$C$87,"AC-*",'Traceability Matrix'!$M$2:$M$87,"Passed")
A6: GRAD-202 | B6: =COUNTIFS('Traceability Matrix'!$B$2:$B$87,"GRAD-202",'Traceability Matrix'!$C$2:$C$87,"AC-*") | C6: =COUNTIFS('Traceability Matrix'!$B$2:$B$87,"GRAD-202",'Traceability Matrix'!$C$2:$C$87,"AC-*",'Traceability Matrix'!$F$2:$F$87,"Tam")+COUNTIFS('Traceability Matrix'!$B$2:$B$87,"GRAD-202",'Traceability Matrix'!$C$2:$C$87,"AC-*",'Traceability Matrix'!$F$2:$F$87,"Tam (çarpaz fayl)") | D6: =COUNTIFS('Traceability Matrix'!$B$2:$B$87,"GRAD-202",'Traceability Matrix'!$C$2:$C$87,"AC-*",'Traceability Matrix'!$F$2:$F$87,"Qismən")+COUNTIFS('Traceability Matrix'!$B$2:$B$87,"GRAD-202",'Traceability Matrix'!$C$2:$C$87,"AC-*",'Traceability Matrix'!$F$2:$F$87,"Qismən (deviation)") | E6: =COUNTIFS('Traceability Matrix'!$B$2:$B$87,"GRAD-202",'Traceability Matrix'!$C$2:$C$87,"AC-*",'Traceability Matrix'!$F$2:$F$87,"YOXDUR") | F6: gradGetCard.spec | G6: =COUNTIFS('Traceability Matrix'!$B$2:$B$87,"GRAD-202",'Traceability Matrix'!$C$2:$C$87,"AC-*",'Traceability Matrix'!$K$2:$K$87,"Avtomat*") | H6: =COUNTIFS('Traceability Matrix'!$B$2:$B$87,"GRAD-202",'Traceability Matrix'!$C$2:$C$87,"AC-*",'Traceability Matrix'!$K$2:$K$87,"YOXDUR") | I6: =COUNTIFS('Traceability Matrix'!$B$2:$B$87,"GRAD-202",'Traceability Matrix'!$C$2:$C$87,"AC-*",'Traceability Matrix'!$L$2:$L$87,"<>") | J6: =COUNTIFS('Traceability Matrix'!$B$2:$B$87,"GRAD-202",'Traceability Matrix'!$C$2:$C$87,"AC-*",'Traceability Matrix'!$M$2:$M$87,"Passed")
A7: GRAD-203 | B7: =COUNTIFS('Traceability Matrix'!$B$2:$B$87,"GRAD-203",'Traceability Matrix'!$C$2:$C$87,"AC-*") | C7: =COUNTIFS('Traceability Matrix'!$B$2:$B$87,"GRAD-203",'Traceability Matrix'!$C$2:$C$87,"AC-*",'Traceability Matrix'!$F$2:$F$87,"Tam")+COUNTIFS('Traceability Matrix'!$B$2:$B$87,"GRAD-203",'Traceability Matrix'!$C$2:$C$87,"AC-*",'Traceability Matrix'!$F$2:$F$87,"Tam (çarpaz fayl)") | D7: =COUNTIFS('Traceability Matrix'!$B$2:$B$87,"GRAD-203",'Traceability Matrix'!$C$2:$C$87,"AC-*",'Traceability Matrix'!$F$2:$F$87,"Qismən")+COUNTIFS('Traceability Matrix'!$B$2:$B$87,"GRAD-203",'Traceability Matrix'!$C$2:$C$87,"AC-*",'Traceability Matrix'!$F$2:$F$87,"Qismən (deviation)") | E7: =COUNTIFS('Traceability Matrix'!$B$2:$B$87,"GRAD-203",'Traceability Matrix'!$C$2:$C$87,"AC-*",'Traceability Matrix'!$F$2:$F$87,"YOXDUR") | F7: gradBlockCard.spec | G7: =COUNTIFS('Traceability Matrix'!$B$2:$B$87,"GRAD-203",'Traceability Matrix'!$C$2:$C$87,"AC-*",'Traceability Matrix'!$K$2:$K$87,"Avtomat*") | H7: =COUNTIFS('Traceability Matrix'!$B$2:$B$87,"GRAD-203",'Traceability Matrix'!$C$2:$C$87,"AC-*",'Traceability Matrix'!$K$2:$K$87,"YOXDUR") | I7: =COUNTIFS('Traceability Matrix'!$B$2:$B$87,"GRAD-203",'Traceability Matrix'!$C$2:$C$87,"AC-*",'Traceability Matrix'!$L$2:$L$87,"<>") | J7: =COUNTIFS('Traceability Matrix'!$B$2:$B$87,"GRAD-203",'Traceability Matrix'!$C$2:$C$87,"AC-*",'Traceability Matrix'!$M$2:$M$87,"Passed")
A8: GRAD-204 | B8: =COUNTIFS('Traceability Matrix'!$B$2:$B$87,"GRAD-204",'Traceability Matrix'!$C$2:$C$87,"AC-*") | C8: =COUNTIFS('Traceability Matrix'!$B$2:$B$87,"GRAD-204",'Traceability Matrix'!$C$2:$C$87,"AC-*",'Traceability Matrix'!$F$2:$F$87,"Tam")+COUNTIFS('Traceability Matrix'!$B$2:$B$87,"GRAD-204",'Traceability Matrix'!$C$2:$C$87,"AC-*",'Traceability Matrix'!$F$2:$F$87,"Tam (çarpaz fayl)") | D8: =COUNTIFS('Traceability Matrix'!$B$2:$B$87,"GRAD-204",'Traceability Matrix'!$C$2:$C$87,"AC-*",'Traceability Matrix'!$F$2:$F$87,"Qismən")+COUNTIFS('Traceability Matrix'!$B$2:$B$87,"GRAD-204",'Traceability Matrix'!$C$2:$C$87,"AC-*",'Traceability Matrix'!$F$2:$F$87,"Qismən (deviation)") | E8: =COUNTIFS('Traceability Matrix'!$B$2:$B$87,"GRAD-204",'Traceability Matrix'!$C$2:$C$87,"AC-*",'Traceability Matrix'!$F$2:$F$87,"YOXDUR") | F8: gradUnblockCard.spec | G8: =COUNTIFS('Traceability Matrix'!$B$2:$B$87,"GRAD-204",'Traceability Matrix'!$C$2:$C$87,"AC-*",'Traceability Matrix'!$K$2:$K$87,"Avtomat*") | H8: =COUNTIFS('Traceability Matrix'!$B$2:$B$87,"GRAD-204",'Traceability Matrix'!$C$2:$C$87,"AC-*",'Traceability Matrix'!$K$2:$K$87,"YOXDUR") | I8: =COUNTIFS('Traceability Matrix'!$B$2:$B$87,"GRAD-204",'Traceability Matrix'!$C$2:$C$87,"AC-*",'Traceability Matrix'!$L$2:$L$87,"<>") | J8: =COUNTIFS('Traceability Matrix'!$B$2:$B$87,"GRAD-204",'Traceability Matrix'!$C$2:$C$87,"AC-*",'Traceability Matrix'!$M$2:$M$87,"Passed")
A9: GRAD-301 | B9: =COUNTIFS('Traceability Matrix'!$B$2:$B$87,"GRAD-301",'Traceability Matrix'!$C$2:$C$87,"AC-*") | C9: =COUNTIFS('Traceability Matrix'!$B$2:$B$87,"GRAD-301",'Traceability Matrix'!$C$2:$C$87,"AC-*",'Traceability Matrix'!$F$2:$F$87,"Tam")+COUNTIFS('Traceability Matrix'!$B$2:$B$87,"GRAD-301",'Traceability Matrix'!$C$2:$C$87,"AC-*",'Traceability Matrix'!$F$2:$F$87,"Tam (çarpaz fayl)") | D9: =COUNTIFS('Traceability Matrix'!$B$2:$B$87,"GRAD-301",'Traceability Matrix'!$C$2:$C$87,"AC-*",'Traceability Matrix'!$F$2:$F$87,"Qismən")+COUNTIFS('Traceability Matrix'!$B$2:$B$87,"GRAD-301",'Traceability Matrix'!$C$2:$C$87,"AC-*",'Traceability Matrix'!$F$2:$F$87,"Qismən (deviation)") | E9: =COUNTIFS('Traceability Matrix'!$B$2:$B$87,"GRAD-301",'Traceability Matrix'!$C$2:$C$87,"AC-*",'Traceability Matrix'!$F$2:$F$87,"YOXDUR") | F9: gradBillersList.spec | G9: =COUNTIFS('Traceability Matrix'!$B$2:$B$87,"GRAD-301",'Traceability Matrix'!$C$2:$C$87,"AC-*",'Traceability Matrix'!$K$2:$K$87,"Avtomat*") | H9: =COUNTIFS('Traceability Matrix'!$B$2:$B$87,"GRAD-301",'Traceability Matrix'!$C$2:$C$87,"AC-*",'Traceability Matrix'!$K$2:$K$87,"YOXDUR") | I9: =COUNTIFS('Traceability Matrix'!$B$2:$B$87,"GRAD-301",'Traceability Matrix'!$C$2:$C$87,"AC-*",'Traceability Matrix'!$L$2:$L$87,"<>") | J9: =COUNTIFS('Traceability Matrix'!$B$2:$B$87,"GRAD-301",'Traceability Matrix'!$C$2:$C$87,"AC-*",'Traceability Matrix'!$M$2:$M$87,"Passed")
A10: GRAD-302 | B10: =COUNTIFS('Traceability Matrix'!$B$2:$B$87,"GRAD-302",'Traceability Matrix'!$C$2:$C$87,"AC-*") | C10: =COUNTIFS('Traceability Matrix'!$B$2:$B$87,"GRAD-302",'Traceability Matrix'!$C$2:$C$87,"AC-*",'Traceability Matrix'!$F$2:$F$87,"Tam")+COUNTIFS('Traceability Matrix'!$B$2:$B$87,"GRAD-302",'Traceability Matrix'!$C$2:$C$87,"AC-*",'Traceability Matrix'!$F$2:$F$87,"Tam (çarpaz fayl)") | D10: =COUNTIFS('Traceability Matrix'!$B$2:$B$87,"GRAD-302",'Traceability Matrix'!$C$2:$C$87,"AC-*",'Traceability Matrix'!$F$2:$F$87,"Qismən")+COUNTIFS('Traceability Matrix'!$B$2:$B$87,"GRAD-302",'Traceability Matrix'!$C$2:$C$87,"AC-*",'Traceability Matrix'!$F$2:$F$87,"Qismən (deviation)") | E10: =COUNTIFS('Traceability Matrix'!$B$2:$B$87,"GRAD-302",'Traceability Matrix'!$C$2:$C$87,"AC-*",'Traceability Matrix'!$F$2:$F$87,"YOXDUR") | F10: gradBillPayments.spec | G10: =COUNTIFS('Traceability Matrix'!$B$2:$B$87,"GRAD-302",'Traceability Matrix'!$C$2:$C$87,"AC-*",'Traceability Matrix'!$K$2:$K$87,"Avtomat*") | H10: =COUNTIFS('Traceability Matrix'!$B$2:$B$87,"GRAD-302",'Traceability Matrix'!$C$2:$C$87,"AC-*",'Traceability Matrix'!$K$2:$K$87,"YOXDUR") | I10: =COUNTIFS('Traceability Matrix'!$B$2:$B$87,"GRAD-302",'Traceability Matrix'!$C$2:$C$87,"AC-*",'Traceability Matrix'!$L$2:$L$87,"<>") | J10: =COUNTIFS('Traceability Matrix'!$B$2:$B$87,"GRAD-302",'Traceability Matrix'!$C$2:$C$87,"AC-*",'Traceability Matrix'!$M$2:$M$87,"Passed")
A11: GRAD-303 | B11: =COUNTIFS('Traceability Matrix'!$B$2:$B$87,"GRAD-303",'Traceability Matrix'!$C$2:$C$87,"AC-*") | C11: =COUNTIFS('Traceability Matrix'!$B$2:$B$87,"GRAD-303",'Traceability Matrix'!$C$2:$C$87,"AC-*",'Traceability Matrix'!$F$2:$F$87,"Tam")+COUNTIFS('Traceability Matrix'!$B$2:$B$87,"GRAD-303",'Traceability Matrix'!$C$2:$C$87,"AC-*",'Traceability Matrix'!$F$2:$F$87,"Tam (çarpaz fayl)") | D11: =COUNTIFS('Traceability Matrix'!$B$2:$B$87,"GRAD-303",'Traceability Matrix'!$C$2:$C$87,"AC-*",'Traceability Matrix'!$F$2:$F$87,"Qismən")+COUNTIFS('Traceability Matrix'!$B$2:$B$87,"GRAD-303",'Traceability Matrix'!$C$2:$C$87,"AC-*",'Traceability Matrix'!$F$2:$F$87,"Qismən (deviation)") | E11: =COUNTIFS('Traceability Matrix'!$B$2:$B$87,"GRAD-303",'Traceability Matrix'!$C$2:$C$87,"AC-*",'Traceability Matrix'!$F$2:$F$87,"YOXDUR") | F11: gradPaymentHistory.spec | G11: =COUNTIFS('Traceability Matrix'!$B$2:$B$87,"GRAD-303",'Traceability Matrix'!$C$2:$C$87,"AC-*",'Traceability Matrix'!$K$2:$K$87,"Avtomat*") | H11: =COUNTIFS('Traceability Matrix'!$B$2:$B$87,"GRAD-303",'Traceability Matrix'!$C$2:$C$87,"AC-*",'Traceability Matrix'!$K$2:$K$87,"YOXDUR") | I11: =COUNTIFS('Traceability Matrix'!$B$2:$B$87,"GRAD-303",'Traceability Matrix'!$C$2:$C$87,"AC-*",'Traceability Matrix'!$L$2:$L$87,"<>") | J11: =COUNTIFS('Traceability Matrix'!$B$2:$B$87,"GRAD-303",'Traceability Matrix'!$C$2:$C$87,"AC-*",'Traceability Matrix'!$M$2:$M$87,"Passed")
A12: CƏMİ | B12: =SUM(B2:B11) | C12: =SUM(C2:C11) | D12: =SUM(D2:D11) | E12: =SUM(E2:E11) | G12: =SUM(G2:G11) | H12: =SUM(H2:H11) | I12: =SUM(I2:I11) | J12: =SUM(J2:J11)
A14: Qeyd: 'Cəmi AC' yalnız nömrələnmiş AC-ləri sayır (Əlavə/Ümumi qaydalar sətirləri xaric). Mənbə: GRAD-AC-Reference.md (verbatim) + mövcud Gauge .spec faylları.
A15: Qeyd (2026-10-07): 'RestAssured' sütunları kodun @Feature/@Story annotasiyalarından çıxarılıb. '2026-10-07 passed' — həmin testin 2026-10-07 icrasında (129/129) keçdiyini göstərir; POJO/JSON Schema refaktorundan sonrakı yenidən icra gözlənilir.
A16: Qeyd (09.10.2026): test case-lərin tam siyahısı, addımları və icra nəticələri yalnız docs/Test-Cases-UI-API.xlsx faylındadır (UI + API). Bu faylın əvvəlki "Test Case-lər (API)" və "Test Case-lər (UI - ASOS)" vərəqləri köhnə ID-lərlə (TC-API-101-01 və s.) dublikat idi və silindi; matrisdəki L sütunu hər AC-ni yeni test case ID-lərinə bağlayır, M sütunu son nəticəni, N sütunu bug-ı göstərir.
