Workbook

Sheet Qeydlər
B2: ASOS.com — Final Layihə: Test Ssenariləri və Test Case-lər
A3: 44+1 ssenari · 235 test case: UI 112 (35 avtomat / 77 manual), API 123 (114 tam + 4 qismən avtomat / 5 manual) | B3: ABB Tech Academy · QA Engineering · Bitirmə layihəsi
B4: 44+1 ssenari (34 UI + 10 API GRAD-101..303 + 1 ümumi qaydalar) · 235 test case: UI 112 (35 avtomat / 77 manual), API 123 (114 tam + 4 qismən avtomat / 5 manual)
B6: Struktur
B7: • "Ssenari və TC (UI)" və "Ssenari və TC (API)" tabları: hər sətir bir test case-dir, özünün ssenarisinin ID/Modul/təsviri ilə birlikdə (sütun 1-3) — ssenari və test case eyni cədvəldə, UI və API ayrı tablarda.
B9: • Tip sütunu rənglə fərqləndirilib: Positive (yaşıl), Negative (qırmızı), Edge/BVA (sarı), Security (bənövşəyi).
B10: • "Manual/Avtomatlaşdırma" sütunu: Avtomatlaşdırma (mavi) / Manual (narıncı) — hər biri "Əsaslandırma" sütununda konkret səbəblə izah olunub.
B11: • "Regression?" sütunu: yalnız Bəli (yaşıl) işarələnmiş case-lər əsas regression suite-inə daxildir və avtomatlaşdırma mərhələsində kodlaşdırılacaq.
B13: Əhatə olunan modullar
B14: • SRCH — Axtarış (search bar, autosuggest)
B15: • PLP — Kateqoriya siyahısı: Filter (Size/Colour/Brand/Price) və Sort
B16: • PDP — Məhsul detalı: ölçü seçimi, şəkillər, Save/wishlist, size guide, tövsiyələr
B17: • BAG — Səbət: miqdar, silmə, promo kod, sessiya davamlılığı
B18: • AUTH — Giriş / Qeydiyyat / Şifrə bərpası
... B58: • Bu journey-lər üçün ayrıca yeni test case yazılmayıb — mövcud case-lər arasında UX-yönümlü əlaqə/ardıcıllıq göstərilib.
A60: Dəyişikliklər — 08.10.2026 (v15)
A62: • API: 3 manual test case əlavə edildi (TC-API-GEN-01/02/03: rate limit, token 24 saat, sandbox sıfırlanması) — tapşırıq səhifəsindəki ümumi qaydalardan.
A63: • API: TC-API-CARD-202-04/05 (GRAD-202 AC-2 və AC-3) və TC-API-CARD-204-06 (GRAD-204 AC-4) əlavə edildi.
A64: • API: TC-API-BEN-102-07 və TC-API-CARD-201-02 "qismən avtomat" oldu (avtomat step-in yoxlaya bilmədiyi hissə manual yoxlanılır).
A65: • API: TC-API-BILL-303-11 06.10-da FAILED oldu — səbəb test kodunda idi (tarix spec-də sabit yazılmışdı); ${today} dəyişəni ilə düzəldildi.
A66: • API: TC-API-BILL-302-01-ə receiptNo formatı (GRAD-302 AC-3) yoxlaması əlavə edildi.
A67: • API: "Əsaslandırma" mətnləri test texnikasına görə (BVA, ekvivalent siniflər, state transition, təhlükəsizlik və s.) yenidən yazıldı.
A68: • UI: TC-AUTH-10/11/15, TC-PLP-06/07/14 Manual-a keçirildi (bot-detection / element yoxdur / UI sıralama step-i yoxdur).
A69: • UI: TC-WISH-03 gözlənilən nəticəsi real davranışa uyğunlaşdırıldı (qonaq save işləyir).
A71: • 08.10 (axşam): UI-da 6 yeni spec yazıldı və icra edildi — SRCH-03/04/06, ERR-03, I18N-02, PDP-03 PASSED.
A72: • 08.10: PLP qiymət locator-u span.price_m0bg_ → span[class^='price_'] (ASOS hashed class dəyişmişdi) — DATA-01 və I18N-01 yenidən PASSED.
A73: • 08.10 TAPINTI: SRCH-08/09 (script/SQL input) avtomatlaşdırılmış brauzerdən Akamai WAF tərəfindən "Access Denied" ilə bloklandı; adi brauzerdə normal — Manual-a keçirildi.
... A80: İcra nəticələri (TC tablarındakı "Nəticə" sütunundan avtomatik hesablanır)
C82: UI | D82: API
B83: Passed | C83: =COUNTIF('Ssenari və TC (UI)'!$Q:$Q,"Passed") -> 107 | D83: =COUNTIF('Ssenari və TC (API)'!$Q:$Q,"Passed") -> 121
B84: Failed | C84: =COUNTIF('Ssenari və TC (UI)'!$Q:$Q,"Failed") -> 1 | D84: =COUNTIF('Ssenari və TC (API)'!$Q:$Q,"Failed") -> 1
B85: Blocked | C85: =COUNTIF('Ssenari və TC (UI)'!$Q:$Q,"Blocked") -> 4 | D85: =COUNTIF('Ssenari və TC (API)'!$Q:$Q,"Blocked") -> 1
B86: Not run | C86: =COUNTIF('Ssenari və TC (UI)'!$Q:$Q,"Not run") -> 0 | D86: =COUNTIF('Ssenari və TC (API)'!$Q:$Q,"Not run") -> 0
B87: Nəticə yazılmayıb | C87: =COUNTA('Ssenari və TC (UI)'!$D:$D)-1-SUM(C83:C86) -> 0 | D87: =COUNTA('Ssenari və TC (API)'!$D:$D)-1-SUM(D83:D86) -> 0
A89: Dəyişikliklər — 09.10.2026 (v18)
A91: • UI və API TC tablarında eyni ssenariyə aid sətirlərin Scenario ID / Modul / Ssenari təsviri xanaları birləşdirildi; ayrı düşmüş sətirlər (TC-WISH-06, TC-CHK-07, TC-NAV-04/05, TC-ERR-03) öz ssenarilərinin yanına köçürüldü.
A92: • Hər iki TC tabına "Brauzer" və "Nəticə" sütunları əlavə edildi. UI: 36 avtomat test Passed (Chrome, Selenium); 13 vacib manual test 09.10.2026-da icra olundu (10 Passed, 1 Failed — TC-AUTH-05, 1 Blocked — TC-BAG-05, 1 Not run — TC-BAG-10), detallar "Qeyd / Nüans" sütunundadır.
A93: • API: 109 tam avtomat test Passed (son tam icra 09.10.2026, 147/147 — bax "Allure Report (API)"). 4 qismən avtomat və 3 manual test üçün Callman nəticəsi hələ yazılmayıb.
A94: • "Bug Report" sheet-i əlavə edildi: BUG-01 (GRAD-302 AC-6, Idempotency-Key olmadan arabir 500).
A95: • 09.10 (axşam): TC-BAG-10/11/12 manual icra olundu — Passed (eyni məhsul Qty 2 kimi bir sətirdə; Qty dropdown-u 1-dən başlayır, 0/mənfi/hərf daxil etmək mümkün deyil). TC-BAG-05: PUMPKINSPICE kodu "məhsul kampaniyaya daxil deyil" mesajı ilə rədd edildi — Blocked qalır.
...

Sheet Ssenari və TC (UI)
A1: Scenario ID | B1: Modul | C1: Ssenari təsviri | D1: TC ID | E1: Başlıq | F1: Tip | G1: Prioritet | H1: Ön şərt (Preconditions) | I1: Addımlar (Steps) | J1: Test Data | K1: Gözlənilən nəticə (Expected Result) | L1: Qeyd / Nüans | M1: Manual/Avtomatlaşdırma | N1: Əsaslandırma (M/A səbəbi) | O1: Regression? | P1: Brauzer | Q1: Nəticə | R1: Gözlənilən nəticənin revizyası
A2: TS-SRCH-01 | B2: SRCH | C2: İstifadəçi axtarış zolağından məhsul axtara bilməli və nəticələr axtarış sözünə uyğun olmalıdır (autosuggest daxil) | D2: TC-SRCH-01 | E2: Doğru açar sözlə axtarış | F2: Positive | G2: High | H2: İstifadəçi asos.com səhifəsindədir | I2: 1) Axtarış zolağına klik et 2) "dress" yaz 3) Enter et | J2: Axtarış sözü: dress | K2: Nəticə səhifəsi açılır; göstərilən məhsulların əksəriyyətinin adı/kateqoriyası "dress" ilə əlaqəlidir; nəticə sayı > 0 | L2: Nəticə sayı canlı stoka görə dəyişir — sabit rəqəmlə deyil, ">0" və məzmun uyğunluğu ilə yoxla Avtomat spec: specs/ui-testing/asos-srch.spec. | M2: Avtomatlaşdırma | N2: Əsas, tez-tez istifadə olunan axtarış axını; nəticə strukturu sabitdir (nisbi assertion: sayı>0, başlıqlar uyğun), sürətli və stabil yoxlanıla bilər — hər build-də run olunmalıdır. | O2: Bəli | P2: Chrome (Selenium, avtomat) | Q2: Passed | R2: Dəyişməyib (icradan əvvəlki gözlənti ilə icra olunub)
D3: TC-SRCH-02 | E3: Autosuggest/auto-complete davranışı | F3: Positive | G3: Medium | H3: İstifadəçi asos.com səhifəsindədir | I3: 1) Axtarış zolağına klik et 2) "dre" yaz (tam söz yazmadan) 3) Görünən təklifləri müşahidə et 4) Ox düymələri ilə aşağı/yuxarı hərəkət et | J3: Qismən axtarış sözü: dre | K3: Açar sözə uyğun təkliflər siyahısı görünür; ox düymələri ilə naviqasiya mümkündür; Enter seçilmiş təklifi açır | L3: UI/vizual davranış MANUAL İCRA (09.10.2026): "dre" yazanda təkliflər siyahısı açıldı (gözlənilən nəticənin 1-ci hissəsi təsdiqləndi). Ox düymələri ilə naviqasiya və Enter ilə seçilmiş təklifin açılması hələ təsdiqlənməyib — nəticə buna görə yazılmayıb. Müşahidə: təklif seçilmədən "dre" mətni ilə birbaşa axtarış edəndə "NOTHING MATCHES YOUR SEARCH" səhifəsi açılır (asos.com/us/discover/no-results-page/?WT.oss=dre) — qismən söz axtarışı nəticə qaytarmır, təkliflər isə qismən sözə görə göstərilir. MANUAL İCRA (09.10.2026, tamamlandı): ox düymələri ilə təkliflər arasında naviqasiya və Enter ilə seçilmiş təklifin açılması da təsdiqləndi — bütün gözlənilən nəticə alındı. | M3: Manual | N3: Dinamik təklif məzmunu tez-tez dəyişir, klaviatura ilə naviqasiya vizual/UX xarakterlidir — avtomatlaşdırma dəyəri aşağıdır. | O3: Xeyr | P3: Google Chrome (manual) | Q3: Passed | R3: Dəyişməyib (icradan əvvəlki gözlənti ilə icra olunub)
D4: TC-SRCH-03 | E4: Mövcud olmayan məhsul üçün axtarış | F4: Negative | G4: Medium | H4: İstifadəçi asos.com səhifəsindədir | I4: 1) Axtarış zolağına mənasız/mövcud olmayan söz yaz (məs. "asdkfjqwe999") 2) Enter et | J4: Axtarış sözü: asdkfjqwe999 | K4: "No results found" (və ya ekvivalent) mesajı göstərilir; səhifə xəta vermir | M4: Avtomatlaşdırma | N4: Deterministik davranış (sabit mesaj), tez run olunur, axtarış funksionallığının pozulmadığını təsdiqləyir. | O4: Bəli | P4: Chrome (Selenium, avtomat) | Q4: Passed | R4: Dəyişməyib (icradan əvvəlki gözlənti ilə icra olunub)
D5: TC-SRCH-04 | E5: Boş axtarış sorğusu | F5: Edge/BVA | G5: Low | H5: İstifadəçi asos.com səhifəsindədir | I5: 1) Axtarış zolağına klik et 2) Heç nə yazmadan Enter et | J5: Axtarış sözü: (boş) | K5: Sistem müəyyən, proqnozlaşdırıla bilən davranış göstərir (axtarış icra olunmur və ya default səhifə açılır) — crash/500 xətası olmur | M5: Avtomatlaşdırma | N5: Aşağı prioritetli, nadir baş verən ssenari; avtomatlaşdırılıb, lakin əsas regression dəstindən kənar, genişləndirilmiş suite-də. | O5: Xeyr | P5: Chrome (Selenium, avtomat) | Q5: Passed | R5: Dəyişməyib (icradan əvvəlki gözlənti ilə icra olunub)
D6: TC-SRCH-05 | E6: Sərhəd uzunluqlu axtarış (1 simvol vs çox uzun) | F6: Edge/BVA | G6: Low | H6: İstifadəçi asos.com səhifəsindədir | I6: 1) 1 simvoldan ibarət axtarış et (məs. "a") 2) Nəticəni qeyd et 3) 200+ simvoldan ibarət təsadüfi mətn axtar | J6: Input: "a" və 200+ simvollu random mətn | K6: Hər iki halda sistem xəta vermədən cavab qaytarır (nəticə var/yoxdur mesajı ilə) | M6: Avtomatlaşdırma | N6: Axtarışın sərhəd uzunluqları (1 və 210 simvol) sabit nəticə verir: səhifə sınmır, input saxlanılır — asos-srch-length.spec ilə avtomatik. | O6: Xeyr | P6: Chrome (Selenium, avtomat) | Q6: Passed | R6: Dəyişməyib (icradan əvvəlki gözlənti ilə icra olunub)
D7: TC-SRCH-06 | E7: Böyük/kiçik hərf həssaslığı | F7: Edge/BVA | G7: Medium | H7: İstifadəçi asos.com səhifəsindədir | I7: 1) "DRESS" ilə axtar, nəticələri qeyd et 2) "dress" ilə axtar, nəticələri müqayisə et | J7: Input: DRESS / dress | K7: Hər iki axtarış eyni (və ya ekvivalent) nəticə dəstini qaytarır | M7: Avtomatlaşdırma | N7: Sadə, sürətli, deterministik müqayisə — case-sensitive axtarış xətası birbaşa istifadəçi təcrübəsinə təsir edir. | O7: Bəli | P7: Chrome (Selenium, avtomat) | Q7: Passed | R7: Dəyişməyib (icradan əvvəlki gözlənti ilə icra olunub)
D8: TC-SRCH-07 | E8: Əvvəl/sonra boşluqlu axtarış | F8: Edge/BVA | G8: Low | H8: İstifadəçi asos.com səhifəsindədir | I8: 1) " dress " (əvvəl/sonra boşluqla) axtar | J8: Input: " dress " | K8: Boşluqlar trim edilir, nəticə "dress" axtarışı ilə eynidir | M8: Avtomatlaşdırma | N8: Boşluqların trim edilməsi "dress" axtarışının nəticə sayı ilə müqayisə edilərək obyektiv yoxlanılır — asos-srch-trim.spec. | O8: Xeyr | P8: Chrome (Selenium, avtomat) | Q8: Passed | R8: Dəyişməyib (icradan əvvəlki gözlənti ilə icra olunub)
A9: TS-SRCH-02 | B9: SRCH | C9: Axtarış sahəsi zərərli/qeyri-standart input-lara qarşı davamlı olmalıdır | D9: TC-SRCH-08 | E9: Axtarış sahəsinə script inject etmə | F9: Security | G9: High | H9: İstifadəçi asos.com səhifəsindədir | I9: 1) Axtarış zolağına `<script>alert(1)</script>` yaz 2) Enter et | J9: Input: <script>alert(1)</script> | K9: Script icra olunmur (alert açılmır), input sadə mətn kimi emal olunur, səhifə normal işləyir | L9: TAPINTI (08.10): production asos.com-un Akamai WAF qatı zərərli görünən axtarış sorğusunu avtomatlaşdırılmış brauzerdən blokladı ("Access Denied"). Bu, təhlükəsizlik qatının işlədiyini göstərir MANUAL İCRA (09.10.2026): 08.10: nəticə səhifəsi normal açıldı, script sadə mətn kimi qaldı, alert açılmadı. 09.10: eyni input Akamai WAF tərəfindən "Access Denied" ilə bloklandı (Reference #18.3e2d1402.1791543183.21333b8b). Hər iki halda script icra olunmadı. | M9: Manual | N9: Selenium ilə icrada Akamai WAF (edgesuite) sorğunu "Access Denied" ilə bloklayır (08.10 skrinşotu, Reference #18.12171002...); adi brauzerdə səhifə normal açılır. Avtomatlaşdırılmış brauzer UI-ın input emalını yoxlaya bilmir — manual icra olunur. | O9: Xeyr | P9: Google Chrome (manual) | Q9: Passed | R9: Dəyişməyib (icradan əvvəlki gözlənti ilə icra olunub)
D10: TC-SRCH-09 | E10: SQL-injection formatlı axtarış inputu | F10: Security | G10: High | H10: İstifadəçi asos.com səhifəsindədir | I10: 1) Axtarış zolağına `' OR '1'='1` yaz 2) Enter et | J10: Input: ' OR '1'='1 | K10: Sorğu təhlükəsizlik qatında (Akamai WAF) bloklanır: "Access Denied" səhifəsi göstərilir; server xətası/stack-trace ifşa olunmur | L10: TAPINTI (08.10): SQL formatlı axtarış həm adi Chrome-da, həm Selenium-da Akamai WAF tərəfindən "Access Denied" ilə bloklanır (Reference #18.17171002...). İlkin gözlənti ("nəticə tapılmadı" səhifəsi) real davranışa uyğunlaşdırıldı MANUAL MÜŞAHİDƏ (09.10.2026): adi Chrome-da da eyni WAF bloku — "Access Denied", www.asos.com/us/search/?, Reference #18.3e2d1402.1791547860.216d705c. | M10: Avtomatlaşdırma | N10: Davranış deterministikdir (adi və avtomatlaşdırılmış brauzerdə eyni WAF bloku); SQL formatlı inputun bloklanması təhlükəsizlik baxımından vacibdir — hər buildə yoxlanılır. | O10: Bəli | P10: Chrome (Selenium, avtomat) | Q10: Passed | R10: [Mühit/təhlükəsizlik qatı] İlkin gözlənti (05.10.2026, icradan əvvəl): "Sistem normal "nəticə tapılmadı" davranışı göstərir; server xətası/stack-trace ifşa olunmur" Səbəb: 08.10: SQL formatlı axtarış həm Selenium-da, həm adi Chrome-da Akamai WAF tərəfindən "Access Denied" (Reference #) ilə bloklanır — davranış deterministikdir. Əsas təhlükəsizlik tələbi (server xətası/stack-trace ifşa olunmur) dəyişməyib; yalnız "nəticə tapılmadı" fərziyyəsi real qoruma qatı ilə əvəz olunub.
A11: TS-PLP-01 | B11: PLP | C11: İstifadəçi kateqoriya səhifəsində filterlərdən (Size/Colour/Brand/Price) istifadə edərək nəticələri daraltmalıdır | D11: TC-PLP-01 | E11: Tək filter tətbiqi (Size) | F11: Positive | G11: High | H11: İstifadəçi bir kateqoriya (məs. Women > Dresses) səhifəsindədir | I11: 1) "Filter" düyməsinə klik et 2) Size bölməsindən bir ölçü seç (məs. UK 10) 3) Tətbiq et | J11: Filter: Size = UK 10 | K11: Yalnız seçilmiş ölçüdə mövcud olan məhsullar göstərilir; nəticə sayı yenilənir | M11: Avtomatlaşdırma | N11: Əsas alış-veriş axınının vacib hissəsi, deterministik nəticə — hər buildə yoxlanmalı core flow. | O11: Bəli | P11: Chrome (Selenium, avtomat) | Q11: Passed | R11: Dəyişməyib (icradan əvvəlki gözlənti ilə icra olunub)
D12: TC-PLP-02 | E12: Bir neçə filterin kombinasiyası | F12: Positive | G12: High | H12: İstifadəçi bir kateqoriya səhifəsindədir | I12: 1) Size filter seç 2) Brand filter əlavə et 3) Price aralığı əlavə et 4) Tətbiq et | J12: Filter: Size + Brand + Price aralığı | K12: Nəticələr HAMISI seçilmiş filterlərə (AND məntiqi) uyğun gəlir | M12: Avtomatlaşdırma | N12: Kombinasiya (AND) məntiqi tez-tez reqressiyaya məruz qalan sahədir — regression dəyərlidir. | O12: Bəli | P12: Chrome (Selenium, avtomat) | Q12: Passed | R12: Dəyişməyib (icradan əvvəlki gözlənti ilə icra olunub)
D13: TC-PLP-03 | E13: Bütün filterlərin təmizlənməsi | F13: Positive | G13: Medium | H13: Ən azı bir filter tətbiq olunub | I13: 1) "Clear all" (və ya ekvivalent) düyməsinə klik et | J13: - | K13: Bütün filterlər sıfırlanır, tam/default məhsul siyahısı qayıdır | L13: 12.10.2026 tam UI regression icrası (39 spec): düşdü — kataloqun maksimum qiyməti 625 → 650 dəyişdi, spec-də sabit yazılmışdı (test kodu defekti, sayt bug-ı deyil). Spec dinamik edildi: slider-in cari sərhəd dəyəri oxunub yaddaşa yazılır və onunla müqayisə olunur. Təkrar icra 12.10.2026 → Passed. | M13: Avtomatlaşdırma | N13: Sadə, sürətli, deterministik — filter reset funksionallığı UI dəyişikliklərindən tez-tez təsirlənir. | O13: Bəli | P13: Chrome (Selenium, avtomat) | Q13: Passed | R13: Dəyişməyib (icradan əvvəlki gözlənti ilə icra olunub)
D14: TC-PLP-04 | E14: Nəticəsi olmayan filter kombinasiyası | F14: Edge/BVA | G14: Medium | H14: İstifadəçi kateqoriya səhifəsindədir | I14: 1) Bir-birinə uyğun gəlməyən dar filterlər seç (məs. nadir ölçü + yüksək qiymət + spesifik brend) | J14: Filter: nəticəsiz kombinasiya | K14: "No items match" (və ya ekvivalent) mesajı göstərilir, səhifə crash olmur | L14: MANUAL İCRA (09.10.2026): Women › Bestselling Clothing: $5–$15 + XL + RED + Tops + Cropped + Main Collection filterləri birlikdə seçildi → "0 styles found", məhsul siyahısı boş, səhifə crash olmadı. Ayrıca "No items match" mətni yoxdur — ekvivalent kimi "0 styles found" sayğacı göstərilir. | M14: Manual | N14: Nəticəsiz filter kombinasiyası production kataloqundan asılıdır — bu gün boş olan kombinasiya sabah məhsul qaytara bilər; sabit test datası yoxdur, manual yoxlanılır. | O14: Xeyr | P14: Google Chrome (manual) | Q14: Passed | R14: Dəyişməyib (icradan əvvəlki gözlənti ilə icra olunub)
D15: TC-PLP-05 | E15: Eyni kateqoriyada (məs. Size) yeni seçimin əvvəlkini əvəz/əlavə etməsi | F15: Edge/BVA | G15: Low | H15: Bir Size filter artıq seçilib | I15: 1) Eyni Size kateqoriyasından ikinci bir dəyər seç 2) Nəticəni müşahidə et | J15: İlk: UK 10, sonra: UK 12 | K15: Sistemin gözlənilən davranışı (multi-select genişlənmə və ya əvəzetmə) ardıcıl və proqnozlaşdırılandır | L15: MANUAL İCRA (09.10.2026): Size filterində əvvəl XS-S, sonra S seçildi → hər iki seçim chip kimi qaldı (əvəz olunmadı), nəticə 1,145 styles. Davranış: multi-select genişlənmə (OR). Test datası UK 10/UK 12 əvəzinə bu kateqoriyadakı XS-S/S ölçüləri ilə icra olundu. | M15: Manual | N15: Filterin UI davranışı vizual/subyektiv qiymətləndirmə tələb edir, tez-tez UI redizaynına məruz qalır. | O15: Xeyr | P15: Google Chrome (manual) | Q15: Passed | R15: Dəyişməyib (icradan əvvəlki gözlənti ilə icra olunub)
A16: TS-PLP-02 | B16: PLP | C16: İstifadəçi nəticələri qiymətə görə sort edə bilməlidir | D16: TC-PLP-06 | E16: "Price: Low to High" sort | F16: Positive | G16: Medium | H16: İstifadəçi nəticə siyahısı olan səhifədədir | I16: 1) Sort menyusunu aç 2) "Price low to high" seç | J16: - | K16: Göstərilən məhsullar qiymətə görə artan sırada düzülür (ardıcıl 10+ elementdə yoxlanılır) | L16: MANUAL İCRA (09.10.2026): Bestselling Clothing (2,526 styles), "Price low to high": $9.95 → $9.99 → $9.99 → $9.99 … — artan sıra. | M16: Manual | N16: Verilmiş arxitekturada UI elementlərinin sırasını (qiymətə görə) müqayisə edən step yoxdur; sıralamanın düzgünlüyü manual yoxlanılır. | O16: Xeyr | P16: Google Chrome (manual) | Q16: Passed | R16: Dəyişməyib (icradan əvvəlki gözlənti ilə icra olunub)
D17: TC-PLP-07 | E17: "Price: High to Low" sort | F17: Positive | G17: Medium | H17: İstifadəçi nəticə siyahısı olan səhifədədir | I17: 1) Sort menyusunu aç 2) "Price high to low" seç | J17: - | K17: Göstərilən məhsullar qiymətə görə azalan sırada düzülür | L17: MANUAL İCRA (09.10.2026): Bestselling Clothing (2,526 styles), "Price high to low": $447.00 → $390.00 → $339.00 → $329.00 … — azalan sıra. | M17: Manual | N17: "Price: High to Low" sort: UI üçün sıralama-müqayisə step-i frameworkdə yoxdur (bax TC-PLP-06). | O17: Xeyr | P17: Google Chrome (manual) | Q17: Passed | R17: Dəyişməyib (icradan əvvəlki gözlənti ilə icra olunub)
D18: TC-PLP-08 | E18: Sort + filter birgə tətbiqi | F18: Edge/BVA | G18: Low | H18: İstifadəçi nəticə siyahısı olan səhifədədir | I18: 1) Bir filter tətbiq et 2) Üzərinə sort tətbiq et | J18: - | K18: Həm filter, həm sort eyni anda qorunur (biri digərini sıfırlamır) | L18: MANUAL İCRA (09.10.2026): Adi Chrome-da əllə də yoxlandı — Passed (avtomat nəticə ilə üst-üstə düşür). | M18: Avtomatlaşdırma | N18: Sort + filter: əvvəl EU 36 ölçü filtri, sonra "Price low to high" sort tətbiq olunur; filtrin URL-də (size:23) qalması və sort radiosunun seçili olması obyektiv yoxlanılır — asos-plp-sort-filter.spec. | O18: Xeyr | P18: Chrome (Selenium, avtomat) + Google Chrome (manual) | Q18: Passed | R18: Dəyişməyib (icradan əvvəlki gözlənti ilə icra olunub)
A19: TS-PLP-03 | B19: PLP | C19: Böyük nəticə dəstlərində səhifələmə/"load more" dublikatsız və dayanıqlı işləməlidir | D19: TC-PLP-09 | E19: "Load more"/scroll ilə əlavə nəticələrin yüklənməsi | F19: Positive | G19: Medium | H19: İstifadəçi çoxsaylı nəticəsi olan kateqoriya səhifəsindədir | I19: 1) Səhifənin sonuna qədər scroll et / "Load more" düyməsinə klik et | J19: - | K19: Əlavə məhsullar yüklənir, əvvəlki nəticələrlə dublikat yaranmır | M19: Avtomatlaşdırma | N19: Böyük kataloqlu saytda tez-tez istifadə olunan funksiya, dublikat riski real reqressiya nöqtəsidir. | O19: Bəli | P19: Chrome (Selenium, avtomat) | Q19: Passed | R19: Dəyişməyib (icradan əvvəlki gözlənti ilə icra olunub)
D20: TC-PLP-10 | E20: Nəticələrin sonunda pagination davranışı | F20: Edge/BVA | G20: Low | H20: İstifadəçi son səhifədədir/bütün nəticələr yüklənib | I20: 1) Bütün nəticələr yüklənənə qədər davam et | J20: - | K20: "Load more" düyməsi itir və ya deaktivləşir; əlavə boş sorğu göndərilmir | L20: MANUAL İCRA (09.10.2026): Bütün nəticələr yükləndikdən sonra davranış yoxlandı — Passed (icra edənin təsdiqi). | M20: Manual | N20: Nadir sərhəd vəziyyəti; avtomatlaşdırma üçün dəyişkən dataset ölçüsü lazımdır, manual dövri yoxlama kifayətdir. | O20: Xeyr | P20: Google Chrome (manual) | Q20: Passed | R20: Dəyişməyib (icradan əvvəlki gözlənti ilə icra olunub)
A21: TS-PDP-01 | B21: PDP | C21: İstifadəçi məhsul detallarını görməli, ölçü seçib çantaya əlavə edə bilməlidir | D21: TC-PDP-01 | E21: Məhsul detalı səhifəsinin açılması | F21: Positive | G21: High | H21: Nəticə siyahısı/axtarışdan bir məhsul mövcuddur | I21: 1) Bir məhsul kartına klik et | J21: - | K21: Məhsul şəkilləri, adı, qiyməti, təsviri, ölçü seçimi görünür | L21: Avtomat spec: asos-pdp-details.spec (PDP-də başlıq və qiymət görünür) + asos-plp.spec (PLP → PDP keçidi, URL "/prd/"). Şəkil/təsvir/ölçü seçiminin görünməsi manual baxışla təsdiqlənib. | M21: Avtomatlaşdırma | N21: Ən əsas, ilk addım flow — hər buildə mütləq işləməlidir, deterministik element mövcudluğu yoxlanışı. | O21: Bəli | P21: Chrome (Selenium, avtomat) | Q21: Passed | R21: Dəyişməyib (icradan əvvəlki gözlənti ilə icra olunub)
D22: TC-PDP-02 | E22: Ölçü seçib çantaya əlavə etmə | F22: Positive | G22: High | H22: İstifadəçi PDP səhifəsindədir | I22: 1) Mövcud bir ölçü seç 2) "Add to Bag" düyməsinə klik et | J22: Ölçü: mövcud olan istənilən ölçü | K22: Məhsul çantaya əlavə olunur; bag ikonundakı say artır; təsdiq bildirişi görünür | L22: MƏHDUDİYYƏT (təsdiqlənib, DevTools Network tab ilə): production asos.com-da bu addımlar Selenium/WebDriver vasitəsilə avtomatlaşdırılıb və klik özü uğurla icra olunur, lakin backend 'getbag' sorğusunu 403 Forbidden ilə rədd edir (manual testdə eyni əməliyyat problemsiz keçir) — anti-bot müdafiə sisteminin WebDriver-i aşkarlayıb bloklaması nəticəsi. Bu, avtomatlaşdırma kodunun səhvi deyil, xarici mühit məhdudiyyətidir. MANUAL İCRA (09.10.2026): Ölçü seçildi, "Add to Bag" → mini-bag açıldı, bag ikonunda say 1 oldu (COLLUSION waffle vest top). | M22: Manual | N22: DÜZƏLİŞ (2026-10-06 audit): bu, bot-detection-in bloklandığı addımın ÖZÜDÜR (Qeyd sütununda öz-özünə sənədləşdirilmiş 403 Forbidden) — Avtomatlaşdırma kimi qalması özünə-ziddiyyət idi. Manual-a köçürüldü. Əvvəlki əsaslandırma: Alış-veriş axınının kritik nöqtəsi (revenue-critical) — addımlar (ölçü seçimi, klik) avtomatlaşdırılıb və regression-da saxlanılır. QEYD: production asos.com-da faktiki nəticə (çantaya əlavə) DevTools ilə təsdiqlənmiş bot-detection (403 Forbidden, bax Qeyd/Nüans) səbəbindən Selenium ilə doğrulana bilmir — bu, tanınmış xarici məhdudiyyət kimi sənədləşdirilib, testin öz keyfiyyətinin göstəricisi deyil. | O22: Xeyr | P22: Google Chrome (manual) | Q22: Passed | R22: Dəyişməyib (icradan əvvəlki gözlənti ilə icra olunub)
D23: TC-PDP-03 | E23: Ölçü seçmədən çantaya əlavə cəhdi | F23: Negative | G23: High | H23: İstifadəçi PDP səhifəsindədir, ölçü seçilməyib | I23: 1) Ölçü seçmədən birbaşa "Add to Bag" düyməsinə klik et | J23: - | K23: Sistem xəbərdarlıq göstərir ("please select a size"), məhsul çantaya əlavə olunmur | L23: Xəbərdarlıq mətni (08.10, real yoxlama): "Please select from the available colour and size options". Ölçü seçilmədiyi üçün sorğu serverə getmir — bot-detection təsir etmir | M23: Avtomatlaşdırma | N23: Sadə validasiya yoxlanışı, sürətli və stabil, istifadəçi səhvlərinin düzgün idarə olunmasını təmin edir. | O23: Bəli | P23: Chrome (Selenium, avtomat) | Q23: Passed | R23: Dəyişməyib (icradan əvvəlki gözlənti ilə icra olunub)
D24: TC-PDP-04 | E24: Stokda olmayan ölçünün seçimi | F24: Edge/BVA | G24: Medium | H24: Seçilmiş məhsulda ən azı bir ölçü stokda yoxdur | I24: 1) Stokda olmayan ölçüyə klik etməyə cəhd et | J24: Ölçü: stokda olmayan | K24: Həmin ölçü seçilə bilmir/vizual olaraq deaktiv ("out of stock") kimi göstərilir | L24: Test datası: adidas Originals Samba OG (prd/209137410) — 08.10-da UK 3, 5.5–8.5, 13 ölçüləri "Out of stock" idi. Stok dəyişərsə data yenilənməlidir | M24: Avtomatlaşdırma | N24: Stoksuz ölçü: adidas Samba OG ölçü seçicisində "- Out of stock" işarəli seçimlərin mövcudluğu yoxlanılır — asos-pdp-out-of-stock.spec. Stok dəyişə bildiyi üçün regression-da deyil. | O24: Xeyr | P24: Chrome (Selenium, avtomat) | Q24: Passed | R24: Dəyişməyib (icradan əvvəlki gözlənti ilə icra olunub)
A25: TS-PDP-02 | B25: PDP | C25: Məhsul səhifəsindəki köməkçi funksiyalar (şəkil qalereyası, save, size guide, qiymət göstərimi) düzgün işləməlidir | D25: TC-PDP-05 | E25: Şəkil qalereyası/zoom | F25: Positive | G25: Low | H25: İstifadəçi PDP səhifəsindədir | I25: 1) Kiçik şəkillər arasında keçid et 2) Əsas şəklə klik/hover ilə zoom et | J25: - | K25: Bütün şəkillər arasında keçid mümkündür, zoom funksiyası işləyir | L25: MANUAL İCRA (09.10.2026): icra olundu, gözlənilən nəticə alındı (icra edənin təsdiqi). | M25: Manual | N25: Tamamilə vizual keyfiyyət yoxlanışı — insan gözü ilə qiymətləndirmə tələb edir. | O25: Xeyr | P25: Google Chrome (manual) | Q25: Passed | R25: Dəyişməyib (icradan əvvəlki gözlənti ilə icra olunub)
D26: TC-PDP-06 | E26: "Save" (wishlist) ikonuna klik | F26: Positive | G26: Medium | H26: İstifadəçi PDP səhifəsindədir | I26: 1) Save/heart ikonuna klik et | J26: - | K26: Məhsul Saved Items-ə əlavə olunur, ikon "saxlanılıb" vəziyyətinə keçir; login olmayan istifadəçi üçün də işləyir (qonaq save — login/qeydiyyata yönləndirmə yoxdur, bax TC-WISH-03) | L26: Avtomat spec: asos-wish-save-item.spec (login olmayan təmiz brauzer). Gözlənilən nəticə real davranışa uyğunlaşdırılıb — bax TC-WISH-03 (qonaq save işləyir, login tələb olunmur). MANUAL İCRA (12.10.2026, gizli pəncərə, login olmadan): PLP-dəki ilk məhsulun PDP-sində Save (ürək) basıldı → Saved Items səhifəsində məhsul göründü ("1 item") → Passed. | M26: Manual | N26: Saved Items səhifəsi Selenium-idarə olunan brauzerdə açılmır — 12.10 regression icrasında 30 saniyədən çox yüklənmə ikonunda qaldı, adi/gizli Chrome-da isə dərhal açılır; kart locator-u dəyişməyib (DevTools ilə təsdiqləndi). Add to Bag/login-dəki bot-detection ilə eyni xarakterli məhdudiyyətdir → manual icra. Spec söndürülüb (.spec.disabled). | O26: Xeyr | P26: Google Chrome (manual, gizli pəncərə) | Q26: Passed | R26: [Test oracle düzəlişi] İlkin gözlənti (05.10.2026, icradan əvvəl): "Login olunubsa məhsul Saved Items-ə əlavə olunur; olunmayıbsa login/qeydiyyat təklifi göstərilir" Səbəb: 02.10 və 12.10: login olmayan təmiz/gizli brauzerdə Save işləyir, Saved Items-də məhsul görünür — qonaq save ASOS-un dizayn davranışıdır (TC-WISH-03 ilə eyni tapıntı). İlkin "login təklif olunur" gözləntisi sənədə yox, fərziyyəyə əsaslanırdı.
D27: TC-PDP-07 | E27: Size Guide linki | F27: Positive | G27: Low | H27: İstifadəçi PDP səhifəsindədir | I27: 1) "Size Guide" linkinə klik et | J27: - | K27: Size Guide düyməsinə klik edildikdə ölçü cədvəli modalı açılır (başlıq "Size Guide", beynəlxalq ölçü çevirmələri cədvəli) | L27: TAPINTI: real saytda statik "Size Guide" linki artıq mövcud deyil — ASOS onu "Find your Fit Assistant size" (boy/çəkiyə əsaslanan şəxsi tövsiyə modalı) ilə əvəz edib. Avtomatlaşdırma bu real elementə uyğunlaşdırılıb: link kliklənir, "FIT ASSISTANT" başlıqlı modalın açıldığı yoxlanılır. 12.10.2026 tam UI regression icrası (39 spec): düşdü — PLP-dəki ilk məhsulun PDP-sində "Fit Assistant" linki yox, "Size Guide" düyməsi var (data-testid="size-guide-button"); modal ayrıca iframe-dədir (data-testid="size-guide-iframe", başlıq <h1 id="modalTitle">). Locator-lar DevTools ilə təsdiqlənib, spec iframe-ə keçidlə yeniləndi. Təkrar icra 12.10.2026 → Passed. | M27: Avtomatlaşdırma | N27: Link klikinin modalı açması sadə, deterministik yoxlanıla bilər (modal başlığının görünməsi) — statik məzmunun vizual düzgünlüyündən fərqli olaraq, funksional davranış (link işləyirmi) avtomatlaşdırmaya yaxşı uyğun gəlir. | O27: Bəli | P27: Chrome (Selenium, avtomat) | Q27: Passed | R27: [Dəqiqləşdirmə (məqsəd dəyişmir)] İlkin gözlənti (05.10.2026, icradan əvvəl): "Ölçü cədvəli/modal açılır, məlumat oxunaqlıdır" Səbəb: 12.10: məqsəd eynidir (ölçü cədvəli modalı açılır); gözlənti ölçülə bilən etmək üçün dəqiqləşdirildi — modal başlığı "Size Guide" DevTools ilə təsdiqlənib və avtomat yoxlanır.
D28: TC-PDP-08 | E28: Endirimli məhsulda qiymət göstərimi | F28: Edge/BVA | G28: Medium | H28: Endirimdə olan bir məhsul mövcuddur | I28: 1) Endirimli bir məhsulun PDP səhifəsini aç | J28: - | K28: Köhnə qiymət (üstü xətli) və yeni endirimli qiymət hər ikisi düzgün göstərilir | L28: Test datası: https://www.asos.com/women/sale/dresses/cat/?cid=5235 (08.10 təsdiqləndi). Menyu ilə keçid Selenium-da etibarsız olduğu üçün birbaşa URL istifadə olunur | M28: Avtomatlaşdırma | N28: Endirim göstərimi: SALE Dresses kateqoriyasından (cid=5235) ilk məhsulun PDP-də köhnə qiymətin (previous-price) cari qiymətlə birlikdə göründüyü yoxlanılır. Sale kateqoriyası daim endirimli məhsul saxladığı üçün data sabitdir; qiymət göstərimi maliyyə baxımından kritikdir — regression. asos-pdp-sale-price.spec. | O28: Bəli | P28: Chrome (Selenium, avtomat) | Q28: Passed | R28: Dəyişməyib (icradan əvvəlki gözlənti ilə icra olunub)
A29: TS-PDP-03 | B29: PDP | C29: Məhsul səhifəsində əlaqəli/tövsiyə olunan məhsullar bölməsi işləməlidir | D29: TC-PDP-09 | E29: "You may also like" bölməsinin işləməsi | F29: Positive | G29: Low | H29: İstifadəçi PDP səhifəsindədir | I29: 1) Səhifəni aşağı scroll et, tövsiyə bölməsini tap 2) Bir tövsiyə olunan məhsula klik et | J29: - | K29: Tövsiyə bölməsi görünür, klik olunan məhsulun öz PDP səhifəsi açılır | L29: Tövsiyə məzmunu personalization-a görə dəyişkəndir MANUAL İCRA (09.10.2026): icra olundu, gözlənilən nəticə alındı (icra edənin təsdiqi). | M29: Manual | N29: Tövsiyə alqoritminin məzmunu subyektiv və dəyişkəndir (personalization) — sabit assertion mümkün deyil. | O29: Xeyr | P29: Google Chrome (manual) | Q29: Passed | R29: Dəyişməyib (icradan əvvəlki gözlənti ilə icra olunub)
A30: TS-BAG-01 | B30: BAG | C30: İstifadəçi çantadakı məhsulların miqdarını dəyişə, silə bilməli, cəm düzgün yenilənməlidir | D30: TC-BAG-01 | E30: Məhsul miqdarını artırma | F30: Positive | G30: High | H30: Çantada ən azı 1 məhsul var | I30: 1) Bag səhifəsini aç 2) Bir məhsulun miqdarını artır | J30: Miqdar: 1 → 2 | K30: Miqdar yenilənir, sətir qiyməti və ümumi cəm düzgün yenidən hesablanır | L30: AVTOMATLAŞDIRMA MƏHDUDİYYƏTİ (yalnız Selenium üçün, təsdiqlənib 2026-10-02; manual icraya təsir etmir): "Add to Bag" sorğusu Selenium-idarə olunan brauzerdə həmişə "Sorry, there was an issue adding this item to the bag" xətası ilə uğursuz olur; eyni məhsul+ölçü adi (avtomatlaşdırılmamış) brauzerdə problemsiz əlavə olunur. Bu, AUTH-dakı bot-detection ilə eyni xarakterli, "Add to Bag" sorğusuna tətbiq olunan ayrıca bir məhdudiyyətdir (bax TC-AUTH-01). MANUAL İCRA (09.10.2026): Miqdar dəyişdirildi, sətir qiyməti və cəm düzgün yeniləndi. | M30: Manual | N30: Təsdiqlənib (2026-10-02): "Add to Bag" sorğusu Selenium-da bot-detection ilə bloklanır (bax Qeyd/Nüans), adi brauzerdə işləyir. | O30: Xeyr | P30: Google Chrome (manual) | Q30: Passed | R30: Dəyişməyib (icradan əvvəlki gözlənti ilə icra olunub)
D31: TC-BAG-02 | E31: Məhsulu çantadan silmə | F31: Positive | G31: High | H31: Çantada ən azı 1 məhsul var | I31: 1) Bag səhifəsində məhsulu sil ("Remove") | J31: - | K31: Məhsul siyahıdan çıxır, ümumi cəm və say yenilənir | L31: AVTOMATLAŞDIRMA MƏHDUDİYYƏTİ (yalnız Selenium üçün, təsdiqlənib 2026-10-02; manual icraya təsir etmir): "Add to Bag" sorğusu Selenium-idarə olunan brauzerdə həmişə "Sorry, there was an issue adding this item to the bag" xətası ilə uğursuz olur; eyni məhsul+ölçü adi (avtomatlaşdırılmamış) brauzerdə problemsiz əlavə olunur. Bu, AUTH-dakı bot-detection ilə eyni xarakterli, "Add to Bag" sorğusuna tətbiq olunan ayrıca bir məhdudiyyətdir (bax TC-AUTH-01). MANUAL İCRA (09.10.2026): Məhsul çantadan silindi, cəm və say yeniləndi. | M31: Manual | N31: Məhsulu çantadan silmə: ön şərt — Çantada ən azı 1 məhsul var. Çantaya məhsul əlavə etmək Selenium-da bot-detection ilə bloklandığı üçün bu vəziyyət avtomatik yaradıla bilmir (bax TC-BAG-01) — manual icra. | O31: Xeyr | P31: Google Chrome (manual) | Q31: Passed | R31: Dəyişməyib (icradan əvvəlki gözlənti ilə icra olunub)
D32: TC-BAG-03 | E32: Stok limitindən artıq miqdar seçmə | F32: Edge/BVA | G32: Medium | H32: Çantada stok miqdarı məlum olan məhsul var | I32: 1) Miqdarı mövcud stokdan artıq təyin etməyə cəhd et | J32: Miqdar: stok + 1 | K32: Sistem miqdarı stok həddi ilə məhdudlaşdırır və ya xəbərdarlıq göstərir | L32: Konkret stok səviyyəsi bilinən məhsul tələb edir — data asılıdır MANUAL İCRA (09.10.2026): Qty dropdown-unda 10-dan artıq miqdar seçmək mümkün deyil — sistem miqdarı məhdudlaşdırır. Qeyd: 10-un stok həddi, yoxsa məhsul başına sabit limit olduğu yoxlanmayıb. | M32: Manual | N32: DÜZƏLİŞ (2026-10-06 audit): əvvəllər Avtomatlaşdırma idi, lakin bu ön şərt (çantada məhsul olması) özü "Add to Bag" addımını tələb edir, bu da sənədləşdirilmiş bot-detection bloku altındadır (TC-PDP-02-yə bax, 403 Forbidden). Ön şərtə avtomatik çatmaq mümkün olmadığı üçün Manual-a köçürüldü. Əvvəlki əsaslandırma: Konkret stok səviyyəsindən asılı test datası tələb edir — data asılılığı səbəbindən genişləndirilmiş suite-də. | O32: Xeyr | P32: Google Chrome (manual) | Q32: Passed | R32: Dəyişməyib (icradan əvvəlki gözlənti ilə icra olunub)
D33: TC-BAG-04 | E33: Boş çanta vəziyyəti | F33: Edge/BVA | G33: Low | H33: Çantada heç bir məhsul yoxdur | I33: 1) Bag səhifəsini aç (bütün məhsullar silinmiş vəziyyətdə) | J33: - | K33: "Bag is empty" (və ya ekvivalent) mesajı və alış-verişə davam et təklifi göstərilir | L33: AVTOMATLAŞDIRMA MƏHDUDİYYƏTİ (yalnız Selenium üçün, təsdiqlənib 2026-10-02; manual icraya təsir etmir): "Add to Bag" sorğusu Selenium-idarə olunan brauzerdə həmişə "Sorry, there was an issue adding this item to the bag" xətası ilə uğursuz olur; eyni məhsul+ölçü adi (avtomatlaşdırılmamış) brauzerdə problemsiz əlavə olunur. Bu, AUTH-dakı bot-detection ilə eyni xarakterli, "Add to Bag" sorğusuna tətbiq olunan ayrıca bir məhdudiyyətdir (bax TC-AUTH-01). MANUAL İCRA (09.10.2026): Boş çanta vəziyyəti gözlənilən kimi göstərildi. | M33: Manual | N33: Bag səhifəsinə əməliyyat aparmaq (ön şərt) bot-detection ilə bloklanır (bax TC-BAG-01). | O33: Xeyr | P33: Google Chrome (manual) | Q33: Passed | R33: Dəyişməyib (icradan əvvəlki gözlənti ilə icra olunub)
A34: TS-BAG-02 | B34: BAG | C34: Promo/discount kod tətbiqi düzgün işləməli, səhv kod aydın şəkildə rədd edilməlidir | D34: TC-BAG-05 | E34: Doğru promo kodun tətbiqi | F34: Positive | G34: High | H34: Çantada məhsul var, keçərli promo kod mövcuddur | I34: 1) Promo kod sahəsinə keçərli kod yaz 2) "Apply" et | J34: Promo kod: keçərli test kodu | K34: Endirim tətbiq olunur, ümumi cəm azalır, tətbiq olunan endirim aydın göstərilir | L34: Aktiv kampaniya kodu tələb olunur — kampaniyalar müvəqqətidir, sabit test datası kimi etibarlı deyil MANUAL İCRA (09.10.2026): 1-ci cəhd — PUMPKINSPICE kampaniyaya daxil olmayan məhsulla rədd edildi ("…not included in this promo"), cəm dəyişmədi. 2-ci cəhd — kampaniyaya daxil məhsulla kod tətbiq olundu: "PUMPKINSPICE Saving $18.00 (30%)", yaşıl təsdiq bloku və "Remove" linki göstərildi. Qeyd: promo kod sahəsi bag-da yox, checkout səhifəsindədir ("Got a discount code? Add it in the next step"). | M34: Manual | N34: Keçərli, real aktiv promo kod tələb edir — kampaniyalar müvəqqətidir, avtomatlaşdırılmış test datası kimi etibarlı deyil. | O34: Xeyr | P34: Google Chrome (manual) | Q34: Passed | R34: Dəyişməyib (icradan əvvəlki gözlənti ilə icra olunub)
D35: TC-BAG-06 | E35: Səhv/mövcud olmayan promo kod | F35: Negative | G35: Medium | H35: Çantada məhsul var | I35: 1) Mövcud olmayan kod yaz (məs. "INVALIDCODE123") 2) "Apply" et | J35: Promo kod: INVALIDCODE123 | K35: Aydın xəta mesajı göstərilir ("invalid code"), cəmə heç bir təsir olmur | L35: AVTOMATLAŞDIRMA MƏHDUDİYYƏTİ (yalnız Selenium üçün, təsdiqlənib 2026-10-02; manual icraya təsir etmir): "Add to Bag" sorğusu Selenium-idarə olunan brauzerdə həmişə "Sorry, there was an issue adding this item to the bag" xətası ilə uğursuz olur; eyni məhsul+ölçü adi (avtomatlaşdırılmamış) brauzerdə problemsiz əlavə olunur. Bu, AUTH-dakı bot-detection ilə eyni xarakterli, "Add to Bag" sorğusuna tətbiq olunan ayrıca bir məhdudiyyətdir (bax TC-AUTH-01). MANUAL İCRA (09.10.2026): Mövcud olmayan kod → "Oops! The code you entered doesn't exist. Please check and try again." mesajı göstərildi, endirim tətbiq olunmadı. | M35: Manual | N35: Səhv/mövcud olmayan promo kod: ön şərt — Çantada məhsul var. Çantaya məhsul əlavə etmək Selenium-da bot-detection ilə bloklandığı üçün bu vəziyyət avtomatik yaradıla bilmir (bax TC-BAG-01) — manual icra. | O35: Xeyr | P35: Google Chrome (manual) | Q35: Passed | R35: Dəyişməyib (icradan əvvəlki gözlənti ilə icra olunub)
D36: TC-BAG-07 | E36: Promo kod sahəsinə injection cəhdi | F36: Security | G36: Medium | H36: Çantada məhsul var | I36: 1) Promo kod sahəsinə `<script>alert(1)</script>` və ya `' OR '1'='1` yaz 2) "Apply" et | J36: Input: script/SQLi formatlı mətn | K36: Sistem sadəcə "yanlış kod" kimi rədd edir, heç bir script icra olunmur, server xətası açılmır | L36: AVTOMATLAŞDIRMA MƏHDUDİYYƏTİ (yalnız Selenium üçün, təsdiqlənib 2026-10-02; manual icraya təsir etmir): "Add to Bag" sorğusu Selenium-idarə olunan brauzerdə həmişə "Sorry, there was an issue adding this item to the bag" xətası ilə uğursuz olur; eyni məhsul+ölçü adi (avtomatlaşdırılmamış) brauzerdə problemsiz əlavə olunur. Bu, AUTH-dakı bot-detection ilə eyni xarakterli, "Add to Bag" sorğusuna tətbiq olunan ayrıca bir məhdudiyyətdir (bax TC-AUTH-01). MANUAL İCRA (09.10.2026): Checkout-da (secure.asos.com/us/) promo kod sahəsinə ' OR '1'='1` yazılıb "Apply code" basıldı. Faktiki: kod "mövcud deyil" kimi rədd edilmədi; əvəzində "Sorry, we are unable to apply this promo code right now. Give us a minute and try again." mesajı, həmçinin "OOPS! We're having problems connecting to some checkout services" / "CONNECTING..." pərdəsi göstərildi. Script icra olunmadı, stack-trace görünmədi, cəm dəyişmədi ($69.99). Gözlənilən "yanlış kod" rəddi (TC-BAG-06-dakı kimi) baş vermədi → BUG-02. KÖK SƏBƏB (12.10.2026, DevTools Network): SQL formatlı kodla PUT .../discounts sorğusu 403 qaytarır (Server: AkamaiGhost, "Access Denied") — input WAF-da bloklanır, tətbiqə çatmır (təhlükəsizlik düzgün işləyir). Adi səhv kod (TEST123) eyni sorğuda 400 + "Oops! The code you entered doesn't exist" verir. Uğursuzluğun səbəbi yanıltıcı mesajdır ("Give us a minute and try again") → BUG-02 (Low). | M36: Manual | N36: Promo kod sahəsinə injection cəhdi: ön şərt — Çantada məhsul var. Çantaya məhsul əlavə etmək Selenium-da bot-detection ilə bloklandığı üçün bu vəziyyət avtomatik yaradıla bilmir (bax TC-BAG-01) — manual icra. | O36: Xeyr | P36: Google Chrome (manual) | Q36: Failed | R36: Dəyişməyib (icradan əvvəlki gözlənti ilə icra olunub)
A37: TS-BAG-03 | B37: BAG | C37: Çantanın məzmunu istifadəçi sessiyaları arasında düzgün saxlanılmalıdır | D37: TC-BAG-08 | E37: Login olunmuş istifadəçidə çantanın sessiyalar arası saxlanması | F37: Positive | G37: Medium | H37: İstifadəçi login olub, çantaya məhsul əlavə edib | I37: 1) Çantaya məhsul əlavə et 2) Hesabdan çıxış et 3) Yenidən eyni hesabla daxil ol 4) Çantanı yoxla | J37: - | K37: Əvvəl əlavə edilmiş məhsul çantada qalır | L37: AVTOMATLAŞDIRMA MƏHDUDİYYƏTİ (yalnız Selenium üçün, təsdiqlənib 2026-10-02; manual icraya təsir etmir): "Add to Bag" sorğusu Selenium-idarə olunan brauzerdə həmişə "Sorry, there was an issue adding this item to the bag" xətası ilə uğursuz olur; eyni məhsul+ölçü adi (avtomatlaşdırılmamış) brauzerdə problemsiz əlavə olunur. Bu, AUTH-dakı bot-detection ilə eyni xarakterli, "Add to Bag" sorğusuna tətbiq olunan ayrıca bir məhdudiyyətdir (bax TC-AUTH-01). Əlavə olaraq login özü də ayrıca bloklanıb (bax TC-AUTH-01). MANUAL İCRA (09.10.2026): Login olunmuş hesabda çantadakı məhsul çıxış edib yenidən daxil olduqdan sonra qaldı. | M37: Manual | N37: Həm Add to Bag, həm də login bot-detection ilə bloklanır (bax TC-BAG-01, TC-AUTH-01). | O37: Xeyr | P37: Google Chrome (manual) | Q37: Passed | R37: Dəyişməyib (icradan əvvəlki gözlənti ilə icra olunub)
D38: TC-BAG-09 | E38: Qonaq istifadəçidə çantanın brauzer sessiyasında saxlanması | F38: Edge/BVA | G38: Low | H38: İstifadəçi login olmayıb, çantaya məhsul əlavə edib | I38: 1) Qonaq kimi çantaya məhsul əlavə et 2) Səhifəni yenilə (refresh) 3) Çantanı yoxla | J38: - | K38: Çanta məzmunu (cookie/session əsaslı) saxlanılır, itmir | L38: Brauzer/cookie davranışı test mühitindən asılıdır MANUAL İCRA (09.10.2026): Qonaq kimi səhifə yeniləndikdən sonra çanta məzmunu saxlanıldı. | M38: Manual | N38: Brauzer/cookie davranışı mühitdən asılıdır və avtomatlaşdırılmış mühitdə simulyasiyası etibarsız ola bilər. | O38: Xeyr | P38: Google Chrome (manual) | Q38: Passed | R38: Dəyişməyib (icradan əvvəlki gözlənti ilə icra olunub)
A39: TS-AUTH-01 | B39: AUTH | C39: İstifadəçi doğru məlumatlarla hesaba giriş edə bilməli, səhv giriş cəhdləri təhlükəsiz idarə olunmalıdır | D39: TC-AUTH-01 | E39: Doğru email+şifrə ilə login | F39: Positive | G39: High | H39: Qeydiyyatdan keçmiş test hesabı mövcuddur | I39: 1) Sign in səhifəsini aç 2) Doğru email+şifrə yaz 3) Submit et | J39: Doğru test hesabı məlumatları | K39: İstifadəçi uğurla hesaba daxil olur, hesab adı/ikon header-də görünür | L39: Yalnız özün üçün yaratdığın test hesabından istifadə et. MƏHDUDİYYƏT (təsdiqlənib, DevTools Network tab ilə, 2026-09-30): eyni bot-detection bloku (bax TC-PDP-02) login axınının İLK addımında (email + Continue) da baş verir — backend 'status' sorğusu 403 Forbidden qaytarır, hətta şifrə mərhələsinə çatmadan. Bu, TC-AUTH-01/02/03/06/07-nin hamısına aiddir, çünki bunların hamısı eyni email-submit addımından keçir. MANUAL İCRA (09.10.2026): Doğru email + şifrə ilə giriş uğurlu oldu. Əlavə: Google hesabı ilə də giriş işləyir. | M39: Manual | N39: DÜZƏLİŞ (2026-10-06 audit): əvvəllər Avtomatlaşdırma idi, lakin bu addım production asos.com-un login/qeydiyyat submit addımını tələb edir — bu, sənədləşdirilmiş bot-detection bloku altındadır (DevTools Network tab ilə təsdiqlənib, 403 Forbidden, TC-AUTH-01-ə bax). Submit-ə çatan HEÇ bir test Selenium-da keçə bilməz — Manual-a köçürüldü. Əvvəlki əsaslandırma: Ən kritik core flow (digər authenticated testlər bundan asılıdır), addımlar deterministik şəkildə avtomatlaşdırılıb. QEYD: production asos.com-da email-submit addımı DevTools ilə təsdiqlənmiş bot-detection (403 Forbidden, bax Qeyd/Nüans) səbəbindən şifrə mərhələsinə belə çatmır — xarici mühit məhdudiyyəti kimi sənədləşdirilib. | O39: Xeyr | P39: Google Chrome (manual) | Q39: Passed | R39: Dəyişməyib (icradan əvvəlki gözlənti ilə icra olunub)
D40: TC-AUTH-02 | E40: Səhv şifrə ilə login cəhdi | F40: Negative | G40: High | H40: Qeydiyyatdan keçmiş test hesabı mövcuddur | I40: 1) Doğru email + səhv şifrə yaz 2) Submit et | J40: Doğru email, səhv şifrə | K40: Ümumi "invalid email or password" xətası göstərilir (email-in mövcudluğu ayrıca ifşa olunmur) | L40: Enumeration riski: mesaj "email tapılmadı" ilə "şifrə səhvdir" arasında fərq qoymamalıdır. AVTOMATLAŞDIRMA MƏHDUDİYYƏTİ (yalnız Selenium üçün; manual icraya təsir etmir): eyni email-submit addımı bot-detection ilə bloklanır (bax TC-AUTH-01) — şifrə mərhələsinə belə çatılmır. MANUAL İCRA (09.10.2026): Səhv şifrə ilə giriş rədd edildi. | M40: Manual | N40: DÜZƏLİŞ (2026-10-06 audit): əvvəllər Avtomatlaşdırma idi, lakin bu addım production asos.com-un login/qeydiyyat submit addımını tələb edir — bu, sənədləşdirilmiş bot-detection bloku altındadır (DevTools Network tab ilə təsdiqlənib, 403 Forbidden, TC-AUTH-01-ə bax). Submit-ə çatan HEÇ bir test Selenium-da keçə bilməz — Manual-a köçürüldü. Əvvəlki əsaslandırma: Addımlar deterministikdir. QEYD: TC-AUTH-01-dəki eyni bot-detection bloku bu case-ə də aiddir (eyni email-submit addımı). | O40: Xeyr | P40: Google Chrome (manual) | Q40: Passed | R40: Dəyişməyib (icradan əvvəlki gözlənti ilə icra olunub)
...

Sheet Ssenari və TC (API)
A1: Scenario ID | B1: Modul | C1: Ssenari təsviri | D1: TC ID | E1: Başlıq | F1: Tip | G1: Prioritet | H1: Ön şərt (Preconditions) | I1: Addımlar (Steps) | J1: Test Data | K1: Gözlənilən nəticə (Expected Result) | L1: Qeyd / Nüans | M1: Manual/Avtomatlaşdırma | N1: Əsaslandırma (M/A səbəbi) | O1: Regression? | P1: Brauzer | Q1: Nəticə | R1: Gözlənilən nəticənin revizyası
A2: TS-API-BILL-302 | B2: API-BILL | C2: API: istifadəçi virtual kart vasitəsilə kommunal xidmətlərə (CityNet, Aztelekom, Azərişıq, Azərsu, Azercell, Bakcell) ödəniş edə bilməli; idempotency, fee, limit, balans və valyuta qaydaları server tərəfində düzgün tətbiq olunmalıdır (GRAD-302) | D2: TC-API-BILL-302-01 | E2: Etibarlı ödəniş — CityNet (faiz əsaslı komissiya) | F2: Positive | G2: High | H2: İstifadəçi login olub (POST /auth/login), aktiv virtual kartı var (POST /cards) | I2: POST /bill-payments, Idempotency-Key header ilə, billerId=citynet | J2: cardId, billerId: citynet, subscriberNo: CN123456, amount: 50 | K2: 201; status=SUCCESS; biller.id=citynet; fee=0.5; total=50.5; currency=AZN; balanceAfter=49.5 receiptNo formatı: RCP-YYYYMMDD-000001 (AC-3, sandbox-da ilk ödəniş) | L2: CityNet fee = amount×1% (min 0.20, max 2.00) AC-3: receiptNo formatı regex ilə yoxlanılır; "+1 hər növbəti ödənişdə" hissəsi TC-API-BILL-302-26-da (RestAssured) yoxlanılır | M2: Avtomatlaşdırma | N2: Komissiya hesablaması — Etibarlı ödəniş — CityNet (faiz əsaslı komissiya) (data: cardId, billerId: citynet, subscriberNo: CN123456,…): gözlənilən status 201. Hesablama xətası birbaşa maliyyə itkisidir, nəticə dəqiq rəqəmdir — avtomatik müqayisə. | O2: Bəli | P2: — (API) | Q2: Passed | R2: Dəyişməyib
D3: TC-API-BILL-302-02 | E3: Aztelekom — sabit komissiya (0.50) | F3: Positive | G3: High | H3: İstifadəçi login olub (POST /auth/login), aktiv virtual kartı var (POST /cards) | I3: POST /bill-payments, billerId=aztelekom | J3: billerId: aztelekom, subscriberNo: 1234567, amount: 10 | K3: 201; fee=0.5; total=10.5 | L3: Aztelekom fee = FIXED 0.5 (məbləzdən asılı deyil) | M3: Avtomatlaşdırma | N3: Komissiya hesablaması — Aztelekom — sabit komissiya (0.50) (data: billerId: aztelekom, subscriberNo: 1234567, amount: 10): gözlənilən status 201. Hesablama xətası birbaşa maliyyə itkisidir, nəticə dəqiq rəqəmdir — avtomatik müqayisə. | O3: Bəli | P3: — (API) | Q3: Passed | R3: Dəyişməyib
D4: TC-API-BILL-302-03 | E4: Idempotency-Key header yoxdur | F4: Negative | G4: Medium | H4: İstifadəçi login olub (POST /auth/login), aktiv virtual kartı var (POST /cards) | I4: POST /bill-payments, Idempotency-Key header ƏLAVƏ EDİLMƏDƏN | J4: billerId: citynet, amount: 50 (Idempotency-Key yox) | K4: 400; code=IDEMPOTENCY_KEY_REQUIRED | L4: BUG-01: 7 tam icradan 1-də 400 əvəzinə 500 qaytarıldı (intermittent) — bax "Bug Report" sheet-i. | M4: Avtomatlaşdırma | N4: İkiqat ödəniş riski — Idempotency-Key header yoxdur: gözlənilən status 400. Idempotency pozulsa pul iki dəfə çıxılır; status/header sabitdir — hər buildə. | O4: Bəli | P4: — (API) | Q4: Passed | R4: Dəyişməyib
D5: TC-API-BILL-302-04 | E5: Idempotency-Key çox qısa | F5: Negative | G5: Medium | H5: İstifadəçi login olub (POST /auth/login), aktiv virtual kartı var (POST /cards) | I5: POST /bill-payments, Idempotency-Key="short" | J5: Idempotency-Key: short | K5: 400; code=IDEMPOTENCY_KEY_INVALID | M5: Avtomatlaşdırma | N5: İkiqat ödəniş riski — Idempotency-Key çox qısa: gözlənilən status 400. Idempotency pozulsa pul iki dəfə çıxılır; status/header sabitdir — hər buildə. | O5: Bəli | P5: — (API) | Q5: Passed | R5: Dəyişməyib
D6: TC-API-BILL-302-05 | E6: Eyni Idempotency-Key + eyni body — təkrar göndərmə | F6: Positive | G6: High | H6: İstifadəçi login olub (POST /auth/login), aktiv virtual kartı var (POST /cards) | I6: 1) Eyni Idempotency-Key+body ilə POST (ilk) 2) Eyni Idempotency-Key+body ilə təkrar POST 3) GET /cards/{cardId} ilə balans yoxla | J6: Idempotency-Key: idem-key-074-replay-ccc, billerId: citynet, amount: 50 | K6: İlk sorğu 201; təkrar (replay) sorğu 200 (eyni data); Header "Idempotent-Replay"="true"; kart balansı yalnız 1 dəfə azalır (availableBalance=49.5) | L6: Real API "Idempotent-Replay" header-i QAYTARIR (real .spec mətnində təsdiqləndi, 2026-10-06) — əvvəlki qeyd (header yoxdur) səhv idi, düzəldildi. Kart yaratma (POST /cards) cavabında Location header-i də yoxlanılıb — keçir. | M6: Avtomatlaşdırma | N6: İkiqat ödəniş riski — Eyni Idempotency-Key + eyni body — təkrar göndərmə: gözlənilən "İlk sorğu 201". Idempotency pozulsa pul iki dəfə çıxılır; status/header sabitdir — hər buildə. | O6: Bəli | P6: — (API) | Q6: Passed | R6: Dəyişməyib
D7: TC-API-BILL-302-06 | E7: Eyni Idempotency-Key, fərqli body | F7: Negative | G7: Medium | H7: İstifadəçi login olub (POST /auth/login), aktiv virtual kartı var (POST /cards) | I7: 1) Idempotency-Key ilə POST (amount=50) 2) Eyni Idempotency-Key, fərqli body (amount=60) ilə POST | J7: Idempotency-Key: idem-key-075-conflict-ddd, amount: 50 → 60 | K7: 409; code=IDEMPOTENCY_CONFLICT | M7: Avtomatlaşdırma | N7: İkiqat ödəniş riski — Eyni Idempotency-Key, fərqli body: gözlənilən status 409. Idempotency pozulsa pul iki dəfə çıxılır; status/header sabitdir — hər buildə. | O7: Bəli | P7: — (API) | Q7: Passed | R7: Dəyişməyib
D8: TC-API-BILL-302-07 | E8: Mövcud olmayan billerId | F8: Negative | G8: Medium | H8: İstifadəçi login olub (POST /auth/login), aktiv virtual kartı var (POST /cards) | I8: POST /bill-payments, billerId=faketech (mövcud olmayan) | J8: billerId: faketech | K8: 404; code=BILLER_NOT_FOUND | M8: Avtomatlaşdırma | N8: Ekvivalent sinif (etibarsız) — Mövcud olmayan billerId (data: billerId: faketech): gözlənilən status 404 (koda görə assert). Validasiya pozulsa → hesabdan səhv məbləğin çıxılması; sabit cavab — regression. | O8: Bəli | P8: — (API) | Q8: Passed | R8: Dəyişməyib
D9: TC-API-BILL-302-08 | E9: Mövcud olmayan cardId | F9: Negative | G9: Medium | H9: İstifadəçi login olub | I9: POST /bill-payments, cardId=vcd_notreal (mövcud olmayan) | J9: cardId: vcd_notreal | K9: 404; code=CARD_NOT_FOUND | M9: Avtomatlaşdırma | N9: Ekvivalent sinif (etibarsız) — Mövcud olmayan cardId (data: cardId: vcd_notreal): gözlənilən status 404 (koda görə assert). Validasiya pozulsa → hesabdan səhv məbləğin çıxılması; sabit cavab — regression. | O9: Bəli | P9: — (API) | Q9: Passed | R9: Dəyişməyib
D10: TC-API-BILL-302-09 | E10: Token yoxdur/etibarsızdır | F10: Security | G10: High | H10: — | I10: POST /bill-payments, Authorization header ƏLAVƏ EDİLMƏDƏN | J10: (Authorization header yoxdur) | K10: 401; cavab body-si {"error": "..."} formatındadır — boş olmayan error mətni, code sahəsi yoxdur (schema: unauthorized.json) | L10: Security case — login formuna yox, bill-payment endpoint-inə auth yoxlaması | M10: Avtomatlaşdırma | N10: Autentifikasiya — Token yoxdur/etibarsızdır (BILL-302): token olmadan sorğu 401 qaytarmalıdır. Hər endpoint ayrıca qorunmalıdır; sürətli, sabit yoxlama — regression. | O10: Bəli | P10: — (API) | Q10: Passed | R10: [Dəqiqləşdirmə (məqsəd dəyişmir)] İlkin gözlənti (09.10.2026): "401" Səbəb: 11.10 — status kodu dəyişmədən cavab məzmunu (code, details[].field, schema) əlavə olundu ki, gözlənti RestAssured assertion-ları qədər dəqiq olsun. Test nəticəsinə təsir etmir.
D11: TC-API-BILL-302-10 | E11: amount mətn kimi göndərilir | F11: Negative | G11: Medium | H11: İstifadəçi login olub (POST /auth/login), aktiv virtual kartı var (POST /cards) | I11: POST /bill-payments, amount sahəsi string kimi göndərilir | J11: amount: "10" (number yox, string) | K11: 400; code=VALIDATION_ERROR | M11: Avtomatlaşdırma | N11: Ekvivalent sinif (etibarsız) — amount mətn kimi göndərilir (data: amount: "10" (number yox, string)): gözlənilən status 400 (koda görə assert). Validasiya pozulsa → hesabdan səhv məbləğin çıxılması; sabit cavab — regression. | O11: Bəli | P11: — (API) | Q11: Passed | R11: Dəyişməyib
D12: TC-API-BILL-302-11 | E12: Subscriber format uyğunsuzluğu — Azərişıq | F12: Negative | G12: Medium | H12: İstifadəçi login olub (POST /auth/login), aktiv virtual kartı var (POST /cards) | I12: POST /bill-payments, billerId=azerisiq, subscriberNo formatı uyğun deyil | J12: billerId: azerisiq, subscriberNo: 123 (pattern ^\d{10}$ tələb olunur) | K12: 422; code=INVALID_SUBSCRIBER | L12: Hər biller-in öz subscriberNo pattern-i var (bax Qeyd sütunu, biler aralığı qaydaları) | M12: Avtomatlaşdırma | N12: Ekvivalent sinif (etibarsız) — Subscriber format uyğunsuzluğu — Azərişıq (data: billerId: azerisiq, subscriberNo: 123 (pattern…): gözlənilən status 422 (koda görə assert). Validasiya pozulsa → hesabdan səhv məbləğin çıxılması; sabit cavab — regression. | O12: Bəli | P12: — (API) | Q12: Passed | R12: Dəyişməyib
D13: TC-API-BILL-302-12 | E13: CityNet fee sərhədi — amount=5 (minimuma clamp) | F13: Positive | G13: Medium | H13: İstifadəçi login olub (POST /auth/login), aktiv virtual kartı var (POST /cards) | I13: POST /bill-payments, billerId=citynet, amount=5 (minimum icazəli məbləğ) | J13: billerId: citynet, amount: 5 | K13: 201; fee=0.2 (min clamp); total=5.2 | L13: 1%×5=0.05, min fee 0.20-ya clamp olunur | M13: Avtomatlaşdırma | N13: Komissiya hesablaması — CityNet fee sərhədi — amount=5 (minimuma clamp) (data: billerId: citynet, amount: 5): gözlənilən status 201. Hesablama xətası birbaşa maliyyə itkisidir, nəticə dəqiq rəqəmdir — avtomatik müqayisə. | O13: Bəli | P13: — (API) | Q13: Passed | R13: Dəyişməyib
D14: TC-API-BILL-302-13 | E14: CityNet fee sərhədi — amount=20 (minimum dəqiq) | F14: Positive | G14: Medium | H14: İstifadəçi login olub (POST /auth/login), aktiv virtual kartı var (POST /cards) | I14: POST /bill-payments, billerId=citynet, amount=20 | J14: billerId: citynet, amount: 20 | K14: 201; fee=0.2; total=20.2 | L14: 1%×20=0.20 — min clamp sərhədinə düz düşür | M14: Avtomatlaşdırma | N14: Komissiya hesablaması — CityNet fee sərhədi — amount=20 (minimum dəqiq) (data: billerId: citynet, amount: 20): gözlənilən status 201. Hesablama xətası birbaşa maliyyə itkisidir, nəticə dəqiq rəqəmdir — avtomatik müqayisə. | O14: Bəli | P14: — (API) | Q14: Passed | R14: Dəyişməyib
D15: TC-API-BILL-302-14 | E15: CityNet fee sərhədi — amount=21 (clamp yoxdur) | F15: Positive | G15: Medium | H15: İstifadəçi login olub (POST /auth/login), aktiv virtual kartı var (POST /cards) | I15: POST /bill-payments, billerId=citynet, amount=21 | J15: billerId: citynet, amount: 21 | K15: 201; fee=0.21; total=21.21 | L15: 1%×21=0.21 — clamp artıq tətbiq olunmur | M15: Avtomatlaşdırma | N15: Komissiya hesablaması — CityNet fee sərhədi — amount=21 (clamp yoxdur) (data: billerId: citynet, amount: 21): gözlənilən status 201. Hesablama xətası birbaşa maliyyə itkisidir, nəticə dəqiq rəqəmdir — avtomatik müqayisə. | O15: Bəli | P15: — (API) | Q15: Passed | R15: Dəyişməyib
D16: TC-API-BILL-302-15 | E16: CityNet fee sərhədi — amount=150 (maksimum) | F16: Positive | G16: Medium | H16: İstifadəçi login olub (POST /auth/login), aktiv virtual kartı var (POST /cards) | I16: POST /bill-payments, billerId=citynet, amount=150 (maksimum icazəli məbləğ) | J16: billerId: citynet, amount: 150 | K16: 201; fee=1.5; total=151.5 | L16: 1%×150=1.5 — max fee clamp-dan (2.00) aşağı | M16: Avtomatlaşdırma | N16: Komissiya hesablaması — CityNet fee sərhədi — amount=150 (maksimum) (data: billerId: citynet, amount: 150): gözlənilən status 201. Hesablama xətası birbaşa maliyyə itkisidir, nəticə dəqiq rəqəmdir — avtomatik müqayisə. | O16: Bəli | P16: — (API) | Q16: Passed | R16: Dəyişməyib
D17: TC-API-BILL-302-16 | E17: Amount minimumdan aşağı (CityNet, 4.99) | F17: Negative | G17: Medium | H17: İstifadəçi login olub (POST /auth/login), aktiv virtual kartı var (POST /cards) | I17: POST /bill-payments, billerId=citynet, amount=4.99 (minimumdan aşağı) | J17: billerId: citynet, amount: 4.99 | K17: 422; code=AMOUNT_OUT_OF_RANGE | L17: CityNet aralığı: 5-150 | M17: Avtomatlaşdırma | N17: BVA — Amount minimumdan aşağı (CityNet, 4.99) (data: billerId: citynet, amount: 4.99): sərhəd nöqtəsində gözlənilən status 422. Xətalar ən çox sərhəddə olur; dəqiq giriş/çıxış — data-driven avtomatlaşdırmaya uyğun. | O17: Bəli | P17: — (API) | Q17: Passed | R17: Dəyişməyib
D18: TC-API-BILL-302-17 | E18: Amount maksimumdan yuxarı (CityNet, 150.01) | F18: Negative | G18: Medium | H18: İstifadəçi login olub (POST /auth/login), aktiv virtual kartı var (POST /cards) | I18: POST /bill-payments, billerId=citynet, amount=150.01 (maksimumdan yuxarı) | J18: billerId: citynet, amount: 150.01 | K18: 422; code=AMOUNT_OUT_OF_RANGE | L18: CityNet aralığı: 5-150 | M18: Avtomatlaşdırma | N18: BVA — Amount maksimumdan yuxarı (CityNet, 150.01) (data: billerId: citynet, amount: 150.01): sərhəd nöqtəsində gözlənilən status 422. Xətalar ən çox sərhəddə olur; dəqiq giriş/çıxış — data-driven avtomatlaşdırmaya uyğun. | O18: Bəli | P18: — (API) | Q18: Passed | R18: Dəyişməyib
D19: TC-API-BILL-302-18 | E19: Per-transaction limit (300) aşılır | F19: Negative | G19: High | H19: İstifadəçi login olub (POST /auth/login), aktiv virtual kartı var (POST /cards) | I19: POST /bill-payments, billerId=azerisiq, amount=300.01 (per-transaction limitdən yuxarı) | J19: billerId: azerisiq, amount: 300.01 | K19: 422; code=PER_TRANSACTION_LIMIT | L19: Kart limiti: perTransaction=300 | M19: Avtomatlaşdırma | N19: BVA — Per-transaction limit (300) aşılır (data: billerId: azerisiq, amount: 300.01): sərhəd nöqtəsində gözlənilən status 422. Xətalar ən çox sərhəddə olur; dəqiq giriş/çıxış — data-driven avtomatlaşdırmaya uyğun. | O19: Bəli | P19: — (API) | Q19: Passed | R19: Dəyişməyib
D20: TC-API-BILL-302-19 | E20: Per-transaction limit sərhədi — 300 dəqiq (keçir) | F20: Positive | G20: High | H20: İstifadəçi login olub (POST /auth/login), aktiv virtual kartı var (POST /cards) | I20: POST /bill-payments, billerId=azerisiq, amount=300 (limitə düz düşür) | J20: billerId: azerisiq, amount: 300 | K20: 201; total=300 | L20: perTransaction limitinin özü keçməlidir, yalnız üzəri bloklanır | M20: Avtomatlaşdırma | N20: BVA — Per-transaction limit sərhədi — 300 dəqiq (keçir) (data: billerId: azerisiq, amount: 300): sərhəd nöqtəsində gözlənilən status 201. Xətalar ən çox sərhəddə olur; dəqiq giriş/çıxış — data-driven avtomatlaşdırmaya uyğun. | O20: Bəli | P20: — (API) | Q20: Passed | R20: Dəyişməyib
D21: TC-API-BILL-302-20 | E21: Daily limit (500) aşılır — zəncirvari ödənişlər | F21: Negative | G21: High | H21: İstifadəçi login olub (POST /auth/login), aktiv virtual kartı var (POST /cards) | I21: Ardıcıl 3 POST /bill-payments: 300 → 200 → 1 (cəmi 501, dailyOnline limitindən yuxarı) | J21: amount: 300, 200, 1 (ardıcıl) | K21: 1-ci və 2-ci sorğu 201; 3-cü sorğu 422; code=DAILY_LIMIT_EXCEEDED | L21: Kart limiti: dailyOnline=500 | M21: Avtomatlaşdırma | N21: BVA — Daily limit (500) aşılır — zəncirvari ödənişlər (data: amount: 300, 200, 1 (ardıcıl)): sərhəd nöqtəsində gözlənilən "1-ci və 2-ci sorğu 201". Xətalar ən çox sərhəddə olur; dəqiq giriş/çıxış — data-driven avtomatlaşdırmaya uyğun. | O21: Bəli | P21: — (API) | Q21: Passed | R21: Dəyişməyib
